2025-04-18 02:03:04,901 ERROR scheduler Exception in Enqueue Events for Site emp.co.zw
Traceback (most recent call last):
  File "/mnt/c/Users/HP/neilla/frappe-bench/frappe-bench/apps/frappe/frappe/utils/scheduler.py", line 99, in enqueue_events_for_site
    if is_scheduler_inactive():
       ^^^^^^^^^^^^^^^^^^^^^^^
  File "/mnt/c/Users/HP/neilla/frappe-bench/frappe-bench/apps/frappe/frappe/utils/scheduler.py", line 143, in is_scheduler_inactive
    if is_scheduler_disabled(verbose=verbose):
       ^^^^^^^^^^^^^^^^^^^^^^^^^^^^^^^^^^^^^^
  File "/mnt/c/Users/HP/neilla/frappe-bench/frappe-bench/apps/frappe/frappe/utils/scheduler.py", line 156, in is_scheduler_disabled
    frappe.db.get_single_value("System Settings", "enable_scheduler")
  File "/mnt/c/Users/HP/neilla/frappe-bench/frappe-bench/apps/frappe/frappe/database/database.py", line 837, in get_single_value
    ).run()
      ^^^^^
  File "/mnt/c/Users/HP/neilla/frappe-bench/frappe-bench/apps/frappe/frappe/query_builder/utils.py", line 87, in execute_query
    result = frappe.db.sql(query, params, *args, **kwargs)  # nosemgrep
             ^^^^^^^^^^^^^^^^^^^^^^^^^^^^^^^^^^^^^^^^^^^^^
  File "/mnt/c/Users/HP/neilla/frappe-bench/frappe-bench/apps/frappe/frappe/database/database.py", line 207, in sql
    self.connect()
  File "/mnt/c/Users/HP/neilla/frappe-bench/frappe-bench/apps/frappe/frappe/database/database.py", line 112, in connect
    self._conn: "MariadbConnection" | "PostgresConnection" = self.get_connection()
                                                             ^^^^^^^^^^^^^^^^^^^^^
  File "/mnt/c/Users/HP/neilla/frappe-bench/frappe-bench/apps/frappe/frappe/database/mariadb/database.py", line 107, in get_connection
    conn = self._get_connection()
           ^^^^^^^^^^^^^^^^^^^^^^
  File "/mnt/c/Users/HP/neilla/frappe-bench/frappe-bench/apps/frappe/frappe/database/mariadb/database.py", line 113, in _get_connection
    return self.create_connection()
           ^^^^^^^^^^^^^^^^^^^^^^^^
  File "/mnt/c/Users/HP/neilla/frappe-bench/frappe-bench/apps/frappe/frappe/database/mariadb/database.py", line 116, in create_connection
    return pymysql.connect(**self.get_connection_settings())
           ^^^^^^^^^^^^^^^^^^^^^^^^^^^^^^^^^^^^^^^^^^^^^^^^^
  File "/mnt/c/Users/HP/neilla/frappe-bench/frappe-bench/env/lib/python3.12/site-packages/pymysql/connections.py", line 361, in __init__
    self.connect()
  File "/mnt/c/Users/HP/neilla/frappe-bench/frappe-bench/env/lib/python3.12/site-packages/pymysql/connections.py", line 669, in connect
    self._request_authentication()
  File "/mnt/c/Users/HP/neilla/frappe-bench/frappe-bench/env/lib/python3.12/site-packages/pymysql/connections.py", line 957, in _request_authentication
    auth_packet = self._read_packet()
                  ^^^^^^^^^^^^^^^^^^^
  File "/mnt/c/Users/HP/neilla/frappe-bench/frappe-bench/env/lib/python3.12/site-packages/pymysql/connections.py", line 775, in _read_packet
    packet.raise_for_error()
  File "/mnt/c/Users/HP/neilla/frappe-bench/frappe-bench/env/lib/python3.12/site-packages/pymysql/protocol.py", line 219, in raise_for_error
    err.raise_mysql_exception(self._data)
  File "/mnt/c/Users/HP/neilla/frappe-bench/frappe-bench/env/lib/python3.12/site-packages/pymysql/err.py", line 150, in raise_mysql_exception
    raise errorclass(errno, errval)
pymysql.err.OperationalError: (1049, "Unknown database '_cd931d51eba0e8ef'")
2025-04-18 02:04:05,075 ERROR scheduler Exception in Enqueue Events for Site emp.co.zw
Traceback (most recent call last):
  File "/mnt/c/Users/HP/neilla/frappe-bench/frappe-bench/apps/frappe/frappe/utils/scheduler.py", line 99, in enqueue_events_for_site
    if is_scheduler_inactive():
       ^^^^^^^^^^^^^^^^^^^^^^^
  File "/mnt/c/Users/HP/neilla/frappe-bench/frappe-bench/apps/frappe/frappe/utils/scheduler.py", line 143, in is_scheduler_inactive
    if is_scheduler_disabled(verbose=verbose):
       ^^^^^^^^^^^^^^^^^^^^^^^^^^^^^^^^^^^^^^
  File "/mnt/c/Users/HP/neilla/frappe-bench/frappe-bench/apps/frappe/frappe/utils/scheduler.py", line 156, in is_scheduler_disabled
    frappe.db.get_single_value("System Settings", "enable_scheduler")
  File "/mnt/c/Users/HP/neilla/frappe-bench/frappe-bench/apps/frappe/frappe/database/database.py", line 837, in get_single_value
    ).run()
      ^^^^^
  File "/mnt/c/Users/HP/neilla/frappe-bench/frappe-bench/apps/frappe/frappe/query_builder/utils.py", line 87, in execute_query
    result = frappe.db.sql(query, params, *args, **kwargs)  # nosemgrep
             ^^^^^^^^^^^^^^^^^^^^^^^^^^^^^^^^^^^^^^^^^^^^^
  File "/mnt/c/Users/HP/neilla/frappe-bench/frappe-bench/apps/frappe/frappe/database/database.py", line 207, in sql
    self.connect()
  File "/mnt/c/Users/HP/neilla/frappe-bench/frappe-bench/apps/frappe/frappe/database/database.py", line 112, in connect
    self._conn: "MariadbConnection" | "PostgresConnection" = self.get_connection()
                                                             ^^^^^^^^^^^^^^^^^^^^^
  File "/mnt/c/Users/HP/neilla/frappe-bench/frappe-bench/apps/frappe/frappe/database/mariadb/database.py", line 107, in get_connection
    conn = self._get_connection()
           ^^^^^^^^^^^^^^^^^^^^^^
  File "/mnt/c/Users/HP/neilla/frappe-bench/frappe-bench/apps/frappe/frappe/database/mariadb/database.py", line 113, in _get_connection
    return self.create_connection()
           ^^^^^^^^^^^^^^^^^^^^^^^^
  File "/mnt/c/Users/HP/neilla/frappe-bench/frappe-bench/apps/frappe/frappe/database/mariadb/database.py", line 116, in create_connection
    return pymysql.connect(**self.get_connection_settings())
           ^^^^^^^^^^^^^^^^^^^^^^^^^^^^^^^^^^^^^^^^^^^^^^^^^
  File "/mnt/c/Users/HP/neilla/frappe-bench/frappe-bench/env/lib/python3.12/site-packages/pymysql/connections.py", line 361, in __init__
    self.connect()
  File "/mnt/c/Users/HP/neilla/frappe-bench/frappe-bench/env/lib/python3.12/site-packages/pymysql/connections.py", line 669, in connect
    self._request_authentication()
  File "/mnt/c/Users/HP/neilla/frappe-bench/frappe-bench/env/lib/python3.12/site-packages/pymysql/connections.py", line 957, in _request_authentication
    auth_packet = self._read_packet()
                  ^^^^^^^^^^^^^^^^^^^
  File "/mnt/c/Users/HP/neilla/frappe-bench/frappe-bench/env/lib/python3.12/site-packages/pymysql/connections.py", line 775, in _read_packet
    packet.raise_for_error()
  File "/mnt/c/Users/HP/neilla/frappe-bench/frappe-bench/env/lib/python3.12/site-packages/pymysql/protocol.py", line 219, in raise_for_error
    err.raise_mysql_exception(self._data)
  File "/mnt/c/Users/HP/neilla/frappe-bench/frappe-bench/env/lib/python3.12/site-packages/pymysql/err.py", line 150, in raise_mysql_exception
    raise errorclass(errno, errval)
pymysql.err.OperationalError: (1049, "Unknown database '_cd931d51eba0e8ef'")
2025-04-18 02:05:05,188 ERROR scheduler Exception in Enqueue Events for Site emp.co.zw
Traceback (most recent call last):
  File "/mnt/c/Users/HP/neilla/frappe-bench/frappe-bench/apps/frappe/frappe/utils/scheduler.py", line 99, in enqueue_events_for_site
    if is_scheduler_inactive():
       ^^^^^^^^^^^^^^^^^^^^^^^
  File "/mnt/c/Users/HP/neilla/frappe-bench/frappe-bench/apps/frappe/frappe/utils/scheduler.py", line 143, in is_scheduler_inactive
    if is_scheduler_disabled(verbose=verbose):
       ^^^^^^^^^^^^^^^^^^^^^^^^^^^^^^^^^^^^^^
  File "/mnt/c/Users/HP/neilla/frappe-bench/frappe-bench/apps/frappe/frappe/utils/scheduler.py", line 156, in is_scheduler_disabled
    frappe.db.get_single_value("System Settings", "enable_scheduler")
  File "/mnt/c/Users/HP/neilla/frappe-bench/frappe-bench/apps/frappe/frappe/database/database.py", line 837, in get_single_value
    ).run()
      ^^^^^
  File "/mnt/c/Users/HP/neilla/frappe-bench/frappe-bench/apps/frappe/frappe/query_builder/utils.py", line 87, in execute_query
    result = frappe.db.sql(query, params, *args, **kwargs)  # nosemgrep
             ^^^^^^^^^^^^^^^^^^^^^^^^^^^^^^^^^^^^^^^^^^^^^
  File "/mnt/c/Users/HP/neilla/frappe-bench/frappe-bench/apps/frappe/frappe/database/database.py", line 207, in sql
    self.connect()
  File "/mnt/c/Users/HP/neilla/frappe-bench/frappe-bench/apps/frappe/frappe/database/database.py", line 112, in connect
    self._conn: "MariadbConnection" | "PostgresConnection" = self.get_connection()
                                                             ^^^^^^^^^^^^^^^^^^^^^
  File "/mnt/c/Users/HP/neilla/frappe-bench/frappe-bench/apps/frappe/frappe/database/mariadb/database.py", line 107, in get_connection
    conn = self._get_connection()
           ^^^^^^^^^^^^^^^^^^^^^^
  File "/mnt/c/Users/HP/neilla/frappe-bench/frappe-bench/apps/frappe/frappe/database/mariadb/database.py", line 113, in _get_connection
    return self.create_connection()
           ^^^^^^^^^^^^^^^^^^^^^^^^
  File "/mnt/c/Users/HP/neilla/frappe-bench/frappe-bench/apps/frappe/frappe/database/mariadb/database.py", line 116, in create_connection
    return pymysql.connect(**self.get_connection_settings())
           ^^^^^^^^^^^^^^^^^^^^^^^^^^^^^^^^^^^^^^^^^^^^^^^^^
  File "/mnt/c/Users/HP/neilla/frappe-bench/frappe-bench/env/lib/python3.12/site-packages/pymysql/connections.py", line 361, in __init__
    self.connect()
  File "/mnt/c/Users/HP/neilla/frappe-bench/frappe-bench/env/lib/python3.12/site-packages/pymysql/connections.py", line 669, in connect
    self._request_authentication()
  File "/mnt/c/Users/HP/neilla/frappe-bench/frappe-bench/env/lib/python3.12/site-packages/pymysql/connections.py", line 957, in _request_authentication
    auth_packet = self._read_packet()
                  ^^^^^^^^^^^^^^^^^^^
  File "/mnt/c/Users/HP/neilla/frappe-bench/frappe-bench/env/lib/python3.12/site-packages/pymysql/connections.py", line 775, in _read_packet
    packet.raise_for_error()
  File "/mnt/c/Users/HP/neilla/frappe-bench/frappe-bench/env/lib/python3.12/site-packages/pymysql/protocol.py", line 219, in raise_for_error
    err.raise_mysql_exception(self._data)
  File "/mnt/c/Users/HP/neilla/frappe-bench/frappe-bench/env/lib/python3.12/site-packages/pymysql/err.py", line 150, in raise_mysql_exception
    raise errorclass(errno, errval)
pymysql.err.OperationalError: (1049, "Unknown database '_cd931d51eba0e8ef'")
2025-04-18 02:06:05,295 ERROR scheduler Exception in Enqueue Events for Site emp.co.zw
Traceback (most recent call last):
  File "/mnt/c/Users/HP/neilla/frappe-bench/frappe-bench/apps/frappe/frappe/utils/scheduler.py", line 99, in enqueue_events_for_site
    if is_scheduler_inactive():
       ^^^^^^^^^^^^^^^^^^^^^^^
  File "/mnt/c/Users/HP/neilla/frappe-bench/frappe-bench/apps/frappe/frappe/utils/scheduler.py", line 143, in is_scheduler_inactive
    if is_scheduler_disabled(verbose=verbose):
       ^^^^^^^^^^^^^^^^^^^^^^^^^^^^^^^^^^^^^^
  File "/mnt/c/Users/HP/neilla/frappe-bench/frappe-bench/apps/frappe/frappe/utils/scheduler.py", line 156, in is_scheduler_disabled
    frappe.db.get_single_value("System Settings", "enable_scheduler")
  File "/mnt/c/Users/HP/neilla/frappe-bench/frappe-bench/apps/frappe/frappe/database/database.py", line 837, in get_single_value
    ).run()
      ^^^^^
  File "/mnt/c/Users/HP/neilla/frappe-bench/frappe-bench/apps/frappe/frappe/query_builder/utils.py", line 87, in execute_query
    result = frappe.db.sql(query, params, *args, **kwargs)  # nosemgrep
             ^^^^^^^^^^^^^^^^^^^^^^^^^^^^^^^^^^^^^^^^^^^^^
  File "/mnt/c/Users/HP/neilla/frappe-bench/frappe-bench/apps/frappe/frappe/database/database.py", line 207, in sql
    self.connect()
  File "/mnt/c/Users/HP/neilla/frappe-bench/frappe-bench/apps/frappe/frappe/database/database.py", line 112, in connect
    self._conn: "MariadbConnection" | "PostgresConnection" = self.get_connection()
                                                             ^^^^^^^^^^^^^^^^^^^^^
  File "/mnt/c/Users/HP/neilla/frappe-bench/frappe-bench/apps/frappe/frappe/database/mariadb/database.py", line 107, in get_connection
    conn = self._get_connection()
           ^^^^^^^^^^^^^^^^^^^^^^
  File "/mnt/c/Users/HP/neilla/frappe-bench/frappe-bench/apps/frappe/frappe/database/mariadb/database.py", line 113, in _get_connection
    return self.create_connection()
           ^^^^^^^^^^^^^^^^^^^^^^^^
  File "/mnt/c/Users/HP/neilla/frappe-bench/frappe-bench/apps/frappe/frappe/database/mariadb/database.py", line 116, in create_connection
    return pymysql.connect(**self.get_connection_settings())
           ^^^^^^^^^^^^^^^^^^^^^^^^^^^^^^^^^^^^^^^^^^^^^^^^^
  File "/mnt/c/Users/HP/neilla/frappe-bench/frappe-bench/env/lib/python3.12/site-packages/pymysql/connections.py", line 361, in __init__
    self.connect()
  File "/mnt/c/Users/HP/neilla/frappe-bench/frappe-bench/env/lib/python3.12/site-packages/pymysql/connections.py", line 669, in connect
    self._request_authentication()
  File "/mnt/c/Users/HP/neilla/frappe-bench/frappe-bench/env/lib/python3.12/site-packages/pymysql/connections.py", line 957, in _request_authentication
    auth_packet = self._read_packet()
                  ^^^^^^^^^^^^^^^^^^^
  File "/mnt/c/Users/HP/neilla/frappe-bench/frappe-bench/env/lib/python3.12/site-packages/pymysql/connections.py", line 775, in _read_packet
    packet.raise_for_error()
  File "/mnt/c/Users/HP/neilla/frappe-bench/frappe-bench/env/lib/python3.12/site-packages/pymysql/protocol.py", line 219, in raise_for_error
    err.raise_mysql_exception(self._data)
  File "/mnt/c/Users/HP/neilla/frappe-bench/frappe-bench/env/lib/python3.12/site-packages/pymysql/err.py", line 150, in raise_mysql_exception
    raise errorclass(errno, errval)
pymysql.err.OperationalError: (1049, "Unknown database '_cd931d51eba0e8ef'")
2025-04-18 02:07:05,416 ERROR scheduler Exception in Enqueue Events for Site emp.co.zw
Traceback (most recent call last):
  File "/mnt/c/Users/HP/neilla/frappe-bench/frappe-bench/apps/frappe/frappe/utils/scheduler.py", line 99, in enqueue_events_for_site
    if is_scheduler_inactive():
       ^^^^^^^^^^^^^^^^^^^^^^^
  File "/mnt/c/Users/HP/neilla/frappe-bench/frappe-bench/apps/frappe/frappe/utils/scheduler.py", line 143, in is_scheduler_inactive
    if is_scheduler_disabled(verbose=verbose):
       ^^^^^^^^^^^^^^^^^^^^^^^^^^^^^^^^^^^^^^
  File "/mnt/c/Users/HP/neilla/frappe-bench/frappe-bench/apps/frappe/frappe/utils/scheduler.py", line 156, in is_scheduler_disabled
    frappe.db.get_single_value("System Settings", "enable_scheduler")
  File "/mnt/c/Users/HP/neilla/frappe-bench/frappe-bench/apps/frappe/frappe/database/database.py", line 837, in get_single_value
    ).run()
      ^^^^^
  File "/mnt/c/Users/HP/neilla/frappe-bench/frappe-bench/apps/frappe/frappe/query_builder/utils.py", line 87, in execute_query
    result = frappe.db.sql(query, params, *args, **kwargs)  # nosemgrep
             ^^^^^^^^^^^^^^^^^^^^^^^^^^^^^^^^^^^^^^^^^^^^^
  File "/mnt/c/Users/HP/neilla/frappe-bench/frappe-bench/apps/frappe/frappe/database/database.py", line 207, in sql
    self.connect()
  File "/mnt/c/Users/HP/neilla/frappe-bench/frappe-bench/apps/frappe/frappe/database/database.py", line 112, in connect
    self._conn: "MariadbConnection" | "PostgresConnection" = self.get_connection()
                                                             ^^^^^^^^^^^^^^^^^^^^^
  File "/mnt/c/Users/HP/neilla/frappe-bench/frappe-bench/apps/frappe/frappe/database/mariadb/database.py", line 107, in get_connection
    conn = self._get_connection()
           ^^^^^^^^^^^^^^^^^^^^^^
  File "/mnt/c/Users/HP/neilla/frappe-bench/frappe-bench/apps/frappe/frappe/database/mariadb/database.py", line 113, in _get_connection
    return self.create_connection()
           ^^^^^^^^^^^^^^^^^^^^^^^^
  File "/mnt/c/Users/HP/neilla/frappe-bench/frappe-bench/apps/frappe/frappe/database/mariadb/database.py", line 116, in create_connection
    return pymysql.connect(**self.get_connection_settings())
           ^^^^^^^^^^^^^^^^^^^^^^^^^^^^^^^^^^^^^^^^^^^^^^^^^
  File "/mnt/c/Users/HP/neilla/frappe-bench/frappe-bench/env/lib/python3.12/site-packages/pymysql/connections.py", line 361, in __init__
    self.connect()
  File "/mnt/c/Users/HP/neilla/frappe-bench/frappe-bench/env/lib/python3.12/site-packages/pymysql/connections.py", line 669, in connect
    self._request_authentication()
  File "/mnt/c/Users/HP/neilla/frappe-bench/frappe-bench/env/lib/python3.12/site-packages/pymysql/connections.py", line 957, in _request_authentication
    auth_packet = self._read_packet()
                  ^^^^^^^^^^^^^^^^^^^
  File "/mnt/c/Users/HP/neilla/frappe-bench/frappe-bench/env/lib/python3.12/site-packages/pymysql/connections.py", line 775, in _read_packet
    packet.raise_for_error()
  File "/mnt/c/Users/HP/neilla/frappe-bench/frappe-bench/env/lib/python3.12/site-packages/pymysql/protocol.py", line 219, in raise_for_error
    err.raise_mysql_exception(self._data)
  File "/mnt/c/Users/HP/neilla/frappe-bench/frappe-bench/env/lib/python3.12/site-packages/pymysql/err.py", line 150, in raise_mysql_exception
    raise errorclass(errno, errval)
pymysql.err.OperationalError: (1049, "Unknown database '_cd931d51eba0e8ef'")
2025-04-18 02:08:05,512 ERROR scheduler Exception in Enqueue Events for Site emp.co.zw
Traceback (most recent call last):
  File "/mnt/c/Users/HP/neilla/frappe-bench/frappe-bench/apps/frappe/frappe/utils/scheduler.py", line 99, in enqueue_events_for_site
    if is_scheduler_inactive():
       ^^^^^^^^^^^^^^^^^^^^^^^
  File "/mnt/c/Users/HP/neilla/frappe-bench/frappe-bench/apps/frappe/frappe/utils/scheduler.py", line 143, in is_scheduler_inactive
    if is_scheduler_disabled(verbose=verbose):
       ^^^^^^^^^^^^^^^^^^^^^^^^^^^^^^^^^^^^^^
  File "/mnt/c/Users/HP/neilla/frappe-bench/frappe-bench/apps/frappe/frappe/utils/scheduler.py", line 156, in is_scheduler_disabled
    frappe.db.get_single_value("System Settings", "enable_scheduler")
  File "/mnt/c/Users/HP/neilla/frappe-bench/frappe-bench/apps/frappe/frappe/database/database.py", line 837, in get_single_value
    ).run()
      ^^^^^
  File "/mnt/c/Users/HP/neilla/frappe-bench/frappe-bench/apps/frappe/frappe/query_builder/utils.py", line 87, in execute_query
    result = frappe.db.sql(query, params, *args, **kwargs)  # nosemgrep
             ^^^^^^^^^^^^^^^^^^^^^^^^^^^^^^^^^^^^^^^^^^^^^
  File "/mnt/c/Users/HP/neilla/frappe-bench/frappe-bench/apps/frappe/frappe/database/database.py", line 207, in sql
    self.connect()
  File "/mnt/c/Users/HP/neilla/frappe-bench/frappe-bench/apps/frappe/frappe/database/database.py", line 112, in connect
    self._conn: "MariadbConnection" | "PostgresConnection" = self.get_connection()
                                                             ^^^^^^^^^^^^^^^^^^^^^
  File "/mnt/c/Users/HP/neilla/frappe-bench/frappe-bench/apps/frappe/frappe/database/mariadb/database.py", line 107, in get_connection
    conn = self._get_connection()
           ^^^^^^^^^^^^^^^^^^^^^^
  File "/mnt/c/Users/HP/neilla/frappe-bench/frappe-bench/apps/frappe/frappe/database/mariadb/database.py", line 113, in _get_connection
    return self.create_connection()
           ^^^^^^^^^^^^^^^^^^^^^^^^
  File "/mnt/c/Users/HP/neilla/frappe-bench/frappe-bench/apps/frappe/frappe/database/mariadb/database.py", line 116, in create_connection
    return pymysql.connect(**self.get_connection_settings())
           ^^^^^^^^^^^^^^^^^^^^^^^^^^^^^^^^^^^^^^^^^^^^^^^^^
  File "/mnt/c/Users/HP/neilla/frappe-bench/frappe-bench/env/lib/python3.12/site-packages/pymysql/connections.py", line 361, in __init__
    self.connect()
  File "/mnt/c/Users/HP/neilla/frappe-bench/frappe-bench/env/lib/python3.12/site-packages/pymysql/connections.py", line 669, in connect
    self._request_authentication()
  File "/mnt/c/Users/HP/neilla/frappe-bench/frappe-bench/env/lib/python3.12/site-packages/pymysql/connections.py", line 957, in _request_authentication
    auth_packet = self._read_packet()
                  ^^^^^^^^^^^^^^^^^^^
  File "/mnt/c/Users/HP/neilla/frappe-bench/frappe-bench/env/lib/python3.12/site-packages/pymysql/connections.py", line 775, in _read_packet
    packet.raise_for_error()
  File "/mnt/c/Users/HP/neilla/frappe-bench/frappe-bench/env/lib/python3.12/site-packages/pymysql/protocol.py", line 219, in raise_for_error
    err.raise_mysql_exception(self._data)
  File "/mnt/c/Users/HP/neilla/frappe-bench/frappe-bench/env/lib/python3.12/site-packages/pymysql/err.py", line 150, in raise_mysql_exception
    raise errorclass(errno, errval)
pymysql.err.OperationalError: (1049, "Unknown database '_cd931d51eba0e8ef'")
2025-04-18 02:09:05,615 ERROR scheduler Exception in Enqueue Events for Site emp.co.zw
Traceback (most recent call last):
  File "/mnt/c/Users/HP/neilla/frappe-bench/frappe-bench/apps/frappe/frappe/utils/scheduler.py", line 99, in enqueue_events_for_site
    if is_scheduler_inactive():
       ^^^^^^^^^^^^^^^^^^^^^^^
  File "/mnt/c/Users/HP/neilla/frappe-bench/frappe-bench/apps/frappe/frappe/utils/scheduler.py", line 143, in is_scheduler_inactive
    if is_scheduler_disabled(verbose=verbose):
       ^^^^^^^^^^^^^^^^^^^^^^^^^^^^^^^^^^^^^^
  File "/mnt/c/Users/HP/neilla/frappe-bench/frappe-bench/apps/frappe/frappe/utils/scheduler.py", line 156, in is_scheduler_disabled
    frappe.db.get_single_value("System Settings", "enable_scheduler")
  File "/mnt/c/Users/HP/neilla/frappe-bench/frappe-bench/apps/frappe/frappe/database/database.py", line 837, in get_single_value
    ).run()
      ^^^^^
  File "/mnt/c/Users/HP/neilla/frappe-bench/frappe-bench/apps/frappe/frappe/query_builder/utils.py", line 87, in execute_query
    result = frappe.db.sql(query, params, *args, **kwargs)  # nosemgrep
             ^^^^^^^^^^^^^^^^^^^^^^^^^^^^^^^^^^^^^^^^^^^^^
  File "/mnt/c/Users/HP/neilla/frappe-bench/frappe-bench/apps/frappe/frappe/database/database.py", line 207, in sql
    self.connect()
  File "/mnt/c/Users/HP/neilla/frappe-bench/frappe-bench/apps/frappe/frappe/database/database.py", line 112, in connect
    self._conn: "MariadbConnection" | "PostgresConnection" = self.get_connection()
                                                             ^^^^^^^^^^^^^^^^^^^^^
  File "/mnt/c/Users/HP/neilla/frappe-bench/frappe-bench/apps/frappe/frappe/database/mariadb/database.py", line 107, in get_connection
    conn = self._get_connection()
           ^^^^^^^^^^^^^^^^^^^^^^
  File "/mnt/c/Users/HP/neilla/frappe-bench/frappe-bench/apps/frappe/frappe/database/mariadb/database.py", line 113, in _get_connection
    return self.create_connection()
           ^^^^^^^^^^^^^^^^^^^^^^^^
  File "/mnt/c/Users/HP/neilla/frappe-bench/frappe-bench/apps/frappe/frappe/database/mariadb/database.py", line 116, in create_connection
    return pymysql.connect(**self.get_connection_settings())
           ^^^^^^^^^^^^^^^^^^^^^^^^^^^^^^^^^^^^^^^^^^^^^^^^^
  File "/mnt/c/Users/HP/neilla/frappe-bench/frappe-bench/env/lib/python3.12/site-packages/pymysql/connections.py", line 361, in __init__
    self.connect()
  File "/mnt/c/Users/HP/neilla/frappe-bench/frappe-bench/env/lib/python3.12/site-packages/pymysql/connections.py", line 669, in connect
    self._request_authentication()
  File "/mnt/c/Users/HP/neilla/frappe-bench/frappe-bench/env/lib/python3.12/site-packages/pymysql/connections.py", line 957, in _request_authentication
    auth_packet = self._read_packet()
                  ^^^^^^^^^^^^^^^^^^^
  File "/mnt/c/Users/HP/neilla/frappe-bench/frappe-bench/env/lib/python3.12/site-packages/pymysql/connections.py", line 775, in _read_packet
    packet.raise_for_error()
  File "/mnt/c/Users/HP/neilla/frappe-bench/frappe-bench/env/lib/python3.12/site-packages/pymysql/protocol.py", line 219, in raise_for_error
    err.raise_mysql_exception(self._data)
  File "/mnt/c/Users/HP/neilla/frappe-bench/frappe-bench/env/lib/python3.12/site-packages/pymysql/err.py", line 150, in raise_mysql_exception
    raise errorclass(errno, errval)
pymysql.err.OperationalError: (1049, "Unknown database '_cd931d51eba0e8ef'")
2025-04-18 02:10:05,743 ERROR scheduler Exception in Enqueue Events for Site emp.co.zw
Traceback (most recent call last):
  File "/mnt/c/Users/HP/neilla/frappe-bench/frappe-bench/apps/frappe/frappe/utils/scheduler.py", line 99, in enqueue_events_for_site
    if is_scheduler_inactive():
       ^^^^^^^^^^^^^^^^^^^^^^^
  File "/mnt/c/Users/HP/neilla/frappe-bench/frappe-bench/apps/frappe/frappe/utils/scheduler.py", line 143, in is_scheduler_inactive
    if is_scheduler_disabled(verbose=verbose):
       ^^^^^^^^^^^^^^^^^^^^^^^^^^^^^^^^^^^^^^
  File "/mnt/c/Users/HP/neilla/frappe-bench/frappe-bench/apps/frappe/frappe/utils/scheduler.py", line 156, in is_scheduler_disabled
    frappe.db.get_single_value("System Settings", "enable_scheduler")
  File "/mnt/c/Users/HP/neilla/frappe-bench/frappe-bench/apps/frappe/frappe/database/database.py", line 837, in get_single_value
    ).run()
      ^^^^^
  File "/mnt/c/Users/HP/neilla/frappe-bench/frappe-bench/apps/frappe/frappe/query_builder/utils.py", line 87, in execute_query
    result = frappe.db.sql(query, params, *args, **kwargs)  # nosemgrep
             ^^^^^^^^^^^^^^^^^^^^^^^^^^^^^^^^^^^^^^^^^^^^^
  File "/mnt/c/Users/HP/neilla/frappe-bench/frappe-bench/apps/frappe/frappe/database/database.py", line 207, in sql
    self.connect()
  File "/mnt/c/Users/HP/neilla/frappe-bench/frappe-bench/apps/frappe/frappe/database/database.py", line 112, in connect
    self._conn: "MariadbConnection" | "PostgresConnection" = self.get_connection()
                                                             ^^^^^^^^^^^^^^^^^^^^^
  File "/mnt/c/Users/HP/neilla/frappe-bench/frappe-bench/apps/frappe/frappe/database/mariadb/database.py", line 107, in get_connection
    conn = self._get_connection()
           ^^^^^^^^^^^^^^^^^^^^^^
  File "/mnt/c/Users/HP/neilla/frappe-bench/frappe-bench/apps/frappe/frappe/database/mariadb/database.py", line 113, in _get_connection
    return self.create_connection()
           ^^^^^^^^^^^^^^^^^^^^^^^^
  File "/mnt/c/Users/HP/neilla/frappe-bench/frappe-bench/apps/frappe/frappe/database/mariadb/database.py", line 116, in create_connection
    return pymysql.connect(**self.get_connection_settings())
           ^^^^^^^^^^^^^^^^^^^^^^^^^^^^^^^^^^^^^^^^^^^^^^^^^
  File "/mnt/c/Users/HP/neilla/frappe-bench/frappe-bench/env/lib/python3.12/site-packages/pymysql/connections.py", line 361, in __init__
    self.connect()
  File "/mnt/c/Users/HP/neilla/frappe-bench/frappe-bench/env/lib/python3.12/site-packages/pymysql/connections.py", line 669, in connect
    self._request_authentication()
  File "/mnt/c/Users/HP/neilla/frappe-bench/frappe-bench/env/lib/python3.12/site-packages/pymysql/connections.py", line 957, in _request_authentication
    auth_packet = self._read_packet()
                  ^^^^^^^^^^^^^^^^^^^
  File "/mnt/c/Users/HP/neilla/frappe-bench/frappe-bench/env/lib/python3.12/site-packages/pymysql/connections.py", line 775, in _read_packet
    packet.raise_for_error()
  File "/mnt/c/Users/HP/neilla/frappe-bench/frappe-bench/env/lib/python3.12/site-packages/pymysql/protocol.py", line 219, in raise_for_error
    err.raise_mysql_exception(self._data)
  File "/mnt/c/Users/HP/neilla/frappe-bench/frappe-bench/env/lib/python3.12/site-packages/pymysql/err.py", line 150, in raise_mysql_exception
    raise errorclass(errno, errval)
pymysql.err.OperationalError: (1049, "Unknown database '_cd931d51eba0e8ef'")
2025-04-18 02:11:05,816 ERROR scheduler Exception in Enqueue Events for Site emp.co.zw
Traceback (most recent call last):
  File "/mnt/c/Users/HP/neilla/frappe-bench/frappe-bench/apps/frappe/frappe/utils/scheduler.py", line 99, in enqueue_events_for_site
    if is_scheduler_inactive():
       ^^^^^^^^^^^^^^^^^^^^^^^
  File "/mnt/c/Users/HP/neilla/frappe-bench/frappe-bench/apps/frappe/frappe/utils/scheduler.py", line 143, in is_scheduler_inactive
    if is_scheduler_disabled(verbose=verbose):
       ^^^^^^^^^^^^^^^^^^^^^^^^^^^^^^^^^^^^^^
  File "/mnt/c/Users/HP/neilla/frappe-bench/frappe-bench/apps/frappe/frappe/utils/scheduler.py", line 156, in is_scheduler_disabled
    frappe.db.get_single_value("System Settings", "enable_scheduler")
  File "/mnt/c/Users/HP/neilla/frappe-bench/frappe-bench/apps/frappe/frappe/database/database.py", line 837, in get_single_value
    ).run()
      ^^^^^
  File "/mnt/c/Users/HP/neilla/frappe-bench/frappe-bench/apps/frappe/frappe/query_builder/utils.py", line 87, in execute_query
    result = frappe.db.sql(query, params, *args, **kwargs)  # nosemgrep
             ^^^^^^^^^^^^^^^^^^^^^^^^^^^^^^^^^^^^^^^^^^^^^
  File "/mnt/c/Users/HP/neilla/frappe-bench/frappe-bench/apps/frappe/frappe/database/database.py", line 207, in sql
    self.connect()
  File "/mnt/c/Users/HP/neilla/frappe-bench/frappe-bench/apps/frappe/frappe/database/database.py", line 112, in connect
    self._conn: "MariadbConnection" | "PostgresConnection" = self.get_connection()
                                                             ^^^^^^^^^^^^^^^^^^^^^
  File "/mnt/c/Users/HP/neilla/frappe-bench/frappe-bench/apps/frappe/frappe/database/mariadb/database.py", line 107, in get_connection
    conn = self._get_connection()
           ^^^^^^^^^^^^^^^^^^^^^^
  File "/mnt/c/Users/HP/neilla/frappe-bench/frappe-bench/apps/frappe/frappe/database/mariadb/database.py", line 113, in _get_connection
    return self.create_connection()
           ^^^^^^^^^^^^^^^^^^^^^^^^
  File "/mnt/c/Users/HP/neilla/frappe-bench/frappe-bench/apps/frappe/frappe/database/mariadb/database.py", line 116, in create_connection
    return pymysql.connect(**self.get_connection_settings())
           ^^^^^^^^^^^^^^^^^^^^^^^^^^^^^^^^^^^^^^^^^^^^^^^^^
  File "/mnt/c/Users/HP/neilla/frappe-bench/frappe-bench/env/lib/python3.12/site-packages/pymysql/connections.py", line 361, in __init__
    self.connect()
  File "/mnt/c/Users/HP/neilla/frappe-bench/frappe-bench/env/lib/python3.12/site-packages/pymysql/connections.py", line 669, in connect
    self._request_authentication()
  File "/mnt/c/Users/HP/neilla/frappe-bench/frappe-bench/env/lib/python3.12/site-packages/pymysql/connections.py", line 957, in _request_authentication
    auth_packet = self._read_packet()
                  ^^^^^^^^^^^^^^^^^^^
  File "/mnt/c/Users/HP/neilla/frappe-bench/frappe-bench/env/lib/python3.12/site-packages/pymysql/connections.py", line 775, in _read_packet
    packet.raise_for_error()
  File "/mnt/c/Users/HP/neilla/frappe-bench/frappe-bench/env/lib/python3.12/site-packages/pymysql/protocol.py", line 219, in raise_for_error
    err.raise_mysql_exception(self._data)
  File "/mnt/c/Users/HP/neilla/frappe-bench/frappe-bench/env/lib/python3.12/site-packages/pymysql/err.py", line 150, in raise_mysql_exception
    raise errorclass(errno, errval)
pymysql.err.OperationalError: (1049, "Unknown database '_cd931d51eba0e8ef'")
2025-04-18 02:12:05,910 ERROR scheduler Exception in Enqueue Events for Site emp.co.zw
Traceback (most recent call last):
  File "/mnt/c/Users/HP/neilla/frappe-bench/frappe-bench/apps/frappe/frappe/utils/scheduler.py", line 99, in enqueue_events_for_site
    if is_scheduler_inactive():
       ^^^^^^^^^^^^^^^^^^^^^^^
  File "/mnt/c/Users/HP/neilla/frappe-bench/frappe-bench/apps/frappe/frappe/utils/scheduler.py", line 143, in is_scheduler_inactive
    if is_scheduler_disabled(verbose=verbose):
       ^^^^^^^^^^^^^^^^^^^^^^^^^^^^^^^^^^^^^^
  File "/mnt/c/Users/HP/neilla/frappe-bench/frappe-bench/apps/frappe/frappe/utils/scheduler.py", line 156, in is_scheduler_disabled
    frappe.db.get_single_value("System Settings", "enable_scheduler")
  File "/mnt/c/Users/HP/neilla/frappe-bench/frappe-bench/apps/frappe/frappe/database/database.py", line 837, in get_single_value
    ).run()
      ^^^^^
  File "/mnt/c/Users/HP/neilla/frappe-bench/frappe-bench/apps/frappe/frappe/query_builder/utils.py", line 87, in execute_query
    result = frappe.db.sql(query, params, *args, **kwargs)  # nosemgrep
             ^^^^^^^^^^^^^^^^^^^^^^^^^^^^^^^^^^^^^^^^^^^^^
  File "/mnt/c/Users/HP/neilla/frappe-bench/frappe-bench/apps/frappe/frappe/database/database.py", line 207, in sql
    self.connect()
  File "/mnt/c/Users/HP/neilla/frappe-bench/frappe-bench/apps/frappe/frappe/database/database.py", line 112, in connect
    self._conn: "MariadbConnection" | "PostgresConnection" = self.get_connection()
                                                             ^^^^^^^^^^^^^^^^^^^^^
  File "/mnt/c/Users/HP/neilla/frappe-bench/frappe-bench/apps/frappe/frappe/database/mariadb/database.py", line 107, in get_connection
    conn = self._get_connection()
           ^^^^^^^^^^^^^^^^^^^^^^
  File "/mnt/c/Users/HP/neilla/frappe-bench/frappe-bench/apps/frappe/frappe/database/mariadb/database.py", line 113, in _get_connection
    return self.create_connection()
           ^^^^^^^^^^^^^^^^^^^^^^^^
  File "/mnt/c/Users/HP/neilla/frappe-bench/frappe-bench/apps/frappe/frappe/database/mariadb/database.py", line 116, in create_connection
    return pymysql.connect(**self.get_connection_settings())
           ^^^^^^^^^^^^^^^^^^^^^^^^^^^^^^^^^^^^^^^^^^^^^^^^^
  File "/mnt/c/Users/HP/neilla/frappe-bench/frappe-bench/env/lib/python3.12/site-packages/pymysql/connections.py", line 361, in __init__
    self.connect()
  File "/mnt/c/Users/HP/neilla/frappe-bench/frappe-bench/env/lib/python3.12/site-packages/pymysql/connections.py", line 669, in connect
    self._request_authentication()
  File "/mnt/c/Users/HP/neilla/frappe-bench/frappe-bench/env/lib/python3.12/site-packages/pymysql/connections.py", line 957, in _request_authentication
    auth_packet = self._read_packet()
                  ^^^^^^^^^^^^^^^^^^^
  File "/mnt/c/Users/HP/neilla/frappe-bench/frappe-bench/env/lib/python3.12/site-packages/pymysql/connections.py", line 775, in _read_packet
    packet.raise_for_error()
  File "/mnt/c/Users/HP/neilla/frappe-bench/frappe-bench/env/lib/python3.12/site-packages/pymysql/protocol.py", line 219, in raise_for_error
    err.raise_mysql_exception(self._data)
  File "/mnt/c/Users/HP/neilla/frappe-bench/frappe-bench/env/lib/python3.12/site-packages/pymysql/err.py", line 150, in raise_mysql_exception
    raise errorclass(errno, errval)
pymysql.err.OperationalError: (1049, "Unknown database '_cd931d51eba0e8ef'")
2025-04-18 02:13:06,032 ERROR scheduler Exception in Enqueue Events for Site emp.co.zw
Traceback (most recent call last):
  File "/mnt/c/Users/HP/neilla/frappe-bench/frappe-bench/apps/frappe/frappe/utils/scheduler.py", line 99, in enqueue_events_for_site
    if is_scheduler_inactive():
       ^^^^^^^^^^^^^^^^^^^^^^^
  File "/mnt/c/Users/HP/neilla/frappe-bench/frappe-bench/apps/frappe/frappe/utils/scheduler.py", line 143, in is_scheduler_inactive
    if is_scheduler_disabled(verbose=verbose):
       ^^^^^^^^^^^^^^^^^^^^^^^^^^^^^^^^^^^^^^
  File "/mnt/c/Users/HP/neilla/frappe-bench/frappe-bench/apps/frappe/frappe/utils/scheduler.py", line 156, in is_scheduler_disabled
    frappe.db.get_single_value("System Settings", "enable_scheduler")
  File "/mnt/c/Users/HP/neilla/frappe-bench/frappe-bench/apps/frappe/frappe/database/database.py", line 837, in get_single_value
    ).run()
      ^^^^^
  File "/mnt/c/Users/HP/neilla/frappe-bench/frappe-bench/apps/frappe/frappe/query_builder/utils.py", line 87, in execute_query
    result = frappe.db.sql(query, params, *args, **kwargs)  # nosemgrep
             ^^^^^^^^^^^^^^^^^^^^^^^^^^^^^^^^^^^^^^^^^^^^^
  File "/mnt/c/Users/HP/neilla/frappe-bench/frappe-bench/apps/frappe/frappe/database/database.py", line 207, in sql
    self.connect()
  File "/mnt/c/Users/HP/neilla/frappe-bench/frappe-bench/apps/frappe/frappe/database/database.py", line 112, in connect
    self._conn: "MariadbConnection" | "PostgresConnection" = self.get_connection()
                                                             ^^^^^^^^^^^^^^^^^^^^^
  File "/mnt/c/Users/HP/neilla/frappe-bench/frappe-bench/apps/frappe/frappe/database/mariadb/database.py", line 107, in get_connection
    conn = self._get_connection()
           ^^^^^^^^^^^^^^^^^^^^^^
  File "/mnt/c/Users/HP/neilla/frappe-bench/frappe-bench/apps/frappe/frappe/database/mariadb/database.py", line 113, in _get_connection
    return self.create_connection()
           ^^^^^^^^^^^^^^^^^^^^^^^^
  File "/mnt/c/Users/HP/neilla/frappe-bench/frappe-bench/apps/frappe/frappe/database/mariadb/database.py", line 116, in create_connection
    return pymysql.connect(**self.get_connection_settings())
           ^^^^^^^^^^^^^^^^^^^^^^^^^^^^^^^^^^^^^^^^^^^^^^^^^
  File "/mnt/c/Users/HP/neilla/frappe-bench/frappe-bench/env/lib/python3.12/site-packages/pymysql/connections.py", line 361, in __init__
    self.connect()
  File "/mnt/c/Users/HP/neilla/frappe-bench/frappe-bench/env/lib/python3.12/site-packages/pymysql/connections.py", line 669, in connect
    self._request_authentication()
  File "/mnt/c/Users/HP/neilla/frappe-bench/frappe-bench/env/lib/python3.12/site-packages/pymysql/connections.py", line 957, in _request_authentication
    auth_packet = self._read_packet()
                  ^^^^^^^^^^^^^^^^^^^
  File "/mnt/c/Users/HP/neilla/frappe-bench/frappe-bench/env/lib/python3.12/site-packages/pymysql/connections.py", line 775, in _read_packet
    packet.raise_for_error()
  File "/mnt/c/Users/HP/neilla/frappe-bench/frappe-bench/env/lib/python3.12/site-packages/pymysql/protocol.py", line 219, in raise_for_error
    err.raise_mysql_exception(self._data)
  File "/mnt/c/Users/HP/neilla/frappe-bench/frappe-bench/env/lib/python3.12/site-packages/pymysql/err.py", line 150, in raise_mysql_exception
    raise errorclass(errno, errval)
pymysql.err.OperationalError: (1049, "Unknown database '_cd931d51eba0e8ef'")
2025-04-18 02:14:06,124 ERROR scheduler Exception in Enqueue Events for Site emp.co.zw
Traceback (most recent call last):
  File "/mnt/c/Users/HP/neilla/frappe-bench/frappe-bench/apps/frappe/frappe/utils/scheduler.py", line 99, in enqueue_events_for_site
    if is_scheduler_inactive():
       ^^^^^^^^^^^^^^^^^^^^^^^
  File "/mnt/c/Users/HP/neilla/frappe-bench/frappe-bench/apps/frappe/frappe/utils/scheduler.py", line 143, in is_scheduler_inactive
    if is_scheduler_disabled(verbose=verbose):
       ^^^^^^^^^^^^^^^^^^^^^^^^^^^^^^^^^^^^^^
  File "/mnt/c/Users/HP/neilla/frappe-bench/frappe-bench/apps/frappe/frappe/utils/scheduler.py", line 156, in is_scheduler_disabled
    frappe.db.get_single_value("System Settings", "enable_scheduler")
  File "/mnt/c/Users/HP/neilla/frappe-bench/frappe-bench/apps/frappe/frappe/database/database.py", line 837, in get_single_value
    ).run()
      ^^^^^
  File "/mnt/c/Users/HP/neilla/frappe-bench/frappe-bench/apps/frappe/frappe/query_builder/utils.py", line 87, in execute_query
    result = frappe.db.sql(query, params, *args, **kwargs)  # nosemgrep
             ^^^^^^^^^^^^^^^^^^^^^^^^^^^^^^^^^^^^^^^^^^^^^
  File "/mnt/c/Users/HP/neilla/frappe-bench/frappe-bench/apps/frappe/frappe/database/database.py", line 207, in sql
    self.connect()
  File "/mnt/c/Users/HP/neilla/frappe-bench/frappe-bench/apps/frappe/frappe/database/database.py", line 112, in connect
    self._conn: "MariadbConnection" | "PostgresConnection" = self.get_connection()
                                                             ^^^^^^^^^^^^^^^^^^^^^
  File "/mnt/c/Users/HP/neilla/frappe-bench/frappe-bench/apps/frappe/frappe/database/mariadb/database.py", line 107, in get_connection
    conn = self._get_connection()
           ^^^^^^^^^^^^^^^^^^^^^^
  File "/mnt/c/Users/HP/neilla/frappe-bench/frappe-bench/apps/frappe/frappe/database/mariadb/database.py", line 113, in _get_connection
    return self.create_connection()
           ^^^^^^^^^^^^^^^^^^^^^^^^
  File "/mnt/c/Users/HP/neilla/frappe-bench/frappe-bench/apps/frappe/frappe/database/mariadb/database.py", line 116, in create_connection
    return pymysql.connect(**self.get_connection_settings())
           ^^^^^^^^^^^^^^^^^^^^^^^^^^^^^^^^^^^^^^^^^^^^^^^^^
  File "/mnt/c/Users/HP/neilla/frappe-bench/frappe-bench/env/lib/python3.12/site-packages/pymysql/connections.py", line 361, in __init__
    self.connect()
  File "/mnt/c/Users/HP/neilla/frappe-bench/frappe-bench/env/lib/python3.12/site-packages/pymysql/connections.py", line 669, in connect
    self._request_authentication()
  File "/mnt/c/Users/HP/neilla/frappe-bench/frappe-bench/env/lib/python3.12/site-packages/pymysql/connections.py", line 957, in _request_authentication
    auth_packet = self._read_packet()
                  ^^^^^^^^^^^^^^^^^^^
  File "/mnt/c/Users/HP/neilla/frappe-bench/frappe-bench/env/lib/python3.12/site-packages/pymysql/connections.py", line 775, in _read_packet
    packet.raise_for_error()
  File "/mnt/c/Users/HP/neilla/frappe-bench/frappe-bench/env/lib/python3.12/site-packages/pymysql/protocol.py", line 219, in raise_for_error
    err.raise_mysql_exception(self._data)
  File "/mnt/c/Users/HP/neilla/frappe-bench/frappe-bench/env/lib/python3.12/site-packages/pymysql/err.py", line 150, in raise_mysql_exception
    raise errorclass(errno, errval)
pymysql.err.OperationalError: (1049, "Unknown database '_cd931d51eba0e8ef'")
2025-04-18 02:15:06,201 ERROR scheduler Exception in Enqueue Events for Site emp.co.zw
Traceback (most recent call last):
  File "/mnt/c/Users/HP/neilla/frappe-bench/frappe-bench/apps/frappe/frappe/utils/scheduler.py", line 99, in enqueue_events_for_site
    if is_scheduler_inactive():
       ^^^^^^^^^^^^^^^^^^^^^^^
  File "/mnt/c/Users/HP/neilla/frappe-bench/frappe-bench/apps/frappe/frappe/utils/scheduler.py", line 143, in is_scheduler_inactive
    if is_scheduler_disabled(verbose=verbose):
       ^^^^^^^^^^^^^^^^^^^^^^^^^^^^^^^^^^^^^^
  File "/mnt/c/Users/HP/neilla/frappe-bench/frappe-bench/apps/frappe/frappe/utils/scheduler.py", line 156, in is_scheduler_disabled
    frappe.db.get_single_value("System Settings", "enable_scheduler")
  File "/mnt/c/Users/HP/neilla/frappe-bench/frappe-bench/apps/frappe/frappe/database/database.py", line 837, in get_single_value
    ).run()
      ^^^^^
  File "/mnt/c/Users/HP/neilla/frappe-bench/frappe-bench/apps/frappe/frappe/query_builder/utils.py", line 87, in execute_query
    result = frappe.db.sql(query, params, *args, **kwargs)  # nosemgrep
             ^^^^^^^^^^^^^^^^^^^^^^^^^^^^^^^^^^^^^^^^^^^^^
  File "/mnt/c/Users/HP/neilla/frappe-bench/frappe-bench/apps/frappe/frappe/database/database.py", line 207, in sql
    self.connect()
  File "/mnt/c/Users/HP/neilla/frappe-bench/frappe-bench/apps/frappe/frappe/database/database.py", line 112, in connect
    self._conn: "MariadbConnection" | "PostgresConnection" = self.get_connection()
                                                             ^^^^^^^^^^^^^^^^^^^^^
  File "/mnt/c/Users/HP/neilla/frappe-bench/frappe-bench/apps/frappe/frappe/database/mariadb/database.py", line 107, in get_connection
    conn = self._get_connection()
           ^^^^^^^^^^^^^^^^^^^^^^
  File "/mnt/c/Users/HP/neilla/frappe-bench/frappe-bench/apps/frappe/frappe/database/mariadb/database.py", line 113, in _get_connection
    return self.create_connection()
           ^^^^^^^^^^^^^^^^^^^^^^^^
  File "/mnt/c/Users/HP/neilla/frappe-bench/frappe-bench/apps/frappe/frappe/database/mariadb/database.py", line 116, in create_connection
    return pymysql.connect(**self.get_connection_settings())
           ^^^^^^^^^^^^^^^^^^^^^^^^^^^^^^^^^^^^^^^^^^^^^^^^^
  File "/mnt/c/Users/HP/neilla/frappe-bench/frappe-bench/env/lib/python3.12/site-packages/pymysql/connections.py", line 361, in __init__
    self.connect()
  File "/mnt/c/Users/HP/neilla/frappe-bench/frappe-bench/env/lib/python3.12/site-packages/pymysql/connections.py", line 669, in connect
    self._request_authentication()
  File "/mnt/c/Users/HP/neilla/frappe-bench/frappe-bench/env/lib/python3.12/site-packages/pymysql/connections.py", line 957, in _request_authentication
    auth_packet = self._read_packet()
                  ^^^^^^^^^^^^^^^^^^^
  File "/mnt/c/Users/HP/neilla/frappe-bench/frappe-bench/env/lib/python3.12/site-packages/pymysql/connections.py", line 775, in _read_packet
    packet.raise_for_error()
  File "/mnt/c/Users/HP/neilla/frappe-bench/frappe-bench/env/lib/python3.12/site-packages/pymysql/protocol.py", line 219, in raise_for_error
    err.raise_mysql_exception(self._data)
  File "/mnt/c/Users/HP/neilla/frappe-bench/frappe-bench/env/lib/python3.12/site-packages/pymysql/err.py", line 150, in raise_mysql_exception
    raise errorclass(errno, errval)
pymysql.err.OperationalError: (1049, "Unknown database '_cd931d51eba0e8ef'")
2025-04-18 02:16:06,330 ERROR scheduler Exception in Enqueue Events for Site emp.co.zw
Traceback (most recent call last):
  File "/mnt/c/Users/HP/neilla/frappe-bench/frappe-bench/apps/frappe/frappe/utils/scheduler.py", line 99, in enqueue_events_for_site
    if is_scheduler_inactive():
       ^^^^^^^^^^^^^^^^^^^^^^^
  File "/mnt/c/Users/HP/neilla/frappe-bench/frappe-bench/apps/frappe/frappe/utils/scheduler.py", line 143, in is_scheduler_inactive
    if is_scheduler_disabled(verbose=verbose):
       ^^^^^^^^^^^^^^^^^^^^^^^^^^^^^^^^^^^^^^
  File "/mnt/c/Users/HP/neilla/frappe-bench/frappe-bench/apps/frappe/frappe/utils/scheduler.py", line 156, in is_scheduler_disabled
    frappe.db.get_single_value("System Settings", "enable_scheduler")
  File "/mnt/c/Users/HP/neilla/frappe-bench/frappe-bench/apps/frappe/frappe/database/database.py", line 837, in get_single_value
    ).run()
      ^^^^^
  File "/mnt/c/Users/HP/neilla/frappe-bench/frappe-bench/apps/frappe/frappe/query_builder/utils.py", line 87, in execute_query
    result = frappe.db.sql(query, params, *args, **kwargs)  # nosemgrep
             ^^^^^^^^^^^^^^^^^^^^^^^^^^^^^^^^^^^^^^^^^^^^^
  File "/mnt/c/Users/HP/neilla/frappe-bench/frappe-bench/apps/frappe/frappe/database/database.py", line 207, in sql
    self.connect()
  File "/mnt/c/Users/HP/neilla/frappe-bench/frappe-bench/apps/frappe/frappe/database/database.py", line 112, in connect
    self._conn: "MariadbConnection" | "PostgresConnection" = self.get_connection()
                                                             ^^^^^^^^^^^^^^^^^^^^^
  File "/mnt/c/Users/HP/neilla/frappe-bench/frappe-bench/apps/frappe/frappe/database/mariadb/database.py", line 107, in get_connection
    conn = self._get_connection()
           ^^^^^^^^^^^^^^^^^^^^^^
  File "/mnt/c/Users/HP/neilla/frappe-bench/frappe-bench/apps/frappe/frappe/database/mariadb/database.py", line 113, in _get_connection
    return self.create_connection()
           ^^^^^^^^^^^^^^^^^^^^^^^^
  File "/mnt/c/Users/HP/neilla/frappe-bench/frappe-bench/apps/frappe/frappe/database/mariadb/database.py", line 116, in create_connection
    return pymysql.connect(**self.get_connection_settings())
           ^^^^^^^^^^^^^^^^^^^^^^^^^^^^^^^^^^^^^^^^^^^^^^^^^
  File "/mnt/c/Users/HP/neilla/frappe-bench/frappe-bench/env/lib/python3.12/site-packages/pymysql/connections.py", line 361, in __init__
    self.connect()
  File "/mnt/c/Users/HP/neilla/frappe-bench/frappe-bench/env/lib/python3.12/site-packages/pymysql/connections.py", line 669, in connect
    self._request_authentication()
  File "/mnt/c/Users/HP/neilla/frappe-bench/frappe-bench/env/lib/python3.12/site-packages/pymysql/connections.py", line 957, in _request_authentication
    auth_packet = self._read_packet()
                  ^^^^^^^^^^^^^^^^^^^
  File "/mnt/c/Users/HP/neilla/frappe-bench/frappe-bench/env/lib/python3.12/site-packages/pymysql/connections.py", line 775, in _read_packet
    packet.raise_for_error()
  File "/mnt/c/Users/HP/neilla/frappe-bench/frappe-bench/env/lib/python3.12/site-packages/pymysql/protocol.py", line 219, in raise_for_error
    err.raise_mysql_exception(self._data)
  File "/mnt/c/Users/HP/neilla/frappe-bench/frappe-bench/env/lib/python3.12/site-packages/pymysql/err.py", line 150, in raise_mysql_exception
    raise errorclass(errno, errval)
pymysql.err.OperationalError: (1049, "Unknown database '_cd931d51eba0e8ef'")
2025-04-18 02:17:06,428 ERROR scheduler Exception in Enqueue Events for Site emp.co.zw
Traceback (most recent call last):
  File "/mnt/c/Users/HP/neilla/frappe-bench/frappe-bench/apps/frappe/frappe/utils/scheduler.py", line 99, in enqueue_events_for_site
    if is_scheduler_inactive():
       ^^^^^^^^^^^^^^^^^^^^^^^
  File "/mnt/c/Users/HP/neilla/frappe-bench/frappe-bench/apps/frappe/frappe/utils/scheduler.py", line 143, in is_scheduler_inactive
    if is_scheduler_disabled(verbose=verbose):
       ^^^^^^^^^^^^^^^^^^^^^^^^^^^^^^^^^^^^^^
  File "/mnt/c/Users/HP/neilla/frappe-bench/frappe-bench/apps/frappe/frappe/utils/scheduler.py", line 156, in is_scheduler_disabled
    frappe.db.get_single_value("System Settings", "enable_scheduler")
  File "/mnt/c/Users/HP/neilla/frappe-bench/frappe-bench/apps/frappe/frappe/database/database.py", line 837, in get_single_value
    ).run()
      ^^^^^
  File "/mnt/c/Users/HP/neilla/frappe-bench/frappe-bench/apps/frappe/frappe/query_builder/utils.py", line 87, in execute_query
    result = frappe.db.sql(query, params, *args, **kwargs)  # nosemgrep
             ^^^^^^^^^^^^^^^^^^^^^^^^^^^^^^^^^^^^^^^^^^^^^
  File "/mnt/c/Users/HP/neilla/frappe-bench/frappe-bench/apps/frappe/frappe/database/database.py", line 207, in sql
    self.connect()
  File "/mnt/c/Users/HP/neilla/frappe-bench/frappe-bench/apps/frappe/frappe/database/database.py", line 112, in connect
    self._conn: "MariadbConnection" | "PostgresConnection" = self.get_connection()
                                                             ^^^^^^^^^^^^^^^^^^^^^
  File "/mnt/c/Users/HP/neilla/frappe-bench/frappe-bench/apps/frappe/frappe/database/mariadb/database.py", line 107, in get_connection
    conn = self._get_connection()
           ^^^^^^^^^^^^^^^^^^^^^^
  File "/mnt/c/Users/HP/neilla/frappe-bench/frappe-bench/apps/frappe/frappe/database/mariadb/database.py", line 113, in _get_connection
    return self.create_connection()
           ^^^^^^^^^^^^^^^^^^^^^^^^
  File "/mnt/c/Users/HP/neilla/frappe-bench/frappe-bench/apps/frappe/frappe/database/mariadb/database.py", line 116, in create_connection
    return pymysql.connect(**self.get_connection_settings())
           ^^^^^^^^^^^^^^^^^^^^^^^^^^^^^^^^^^^^^^^^^^^^^^^^^
  File "/mnt/c/Users/HP/neilla/frappe-bench/frappe-bench/env/lib/python3.12/site-packages/pymysql/connections.py", line 361, in __init__
    self.connect()
  File "/mnt/c/Users/HP/neilla/frappe-bench/frappe-bench/env/lib/python3.12/site-packages/pymysql/connections.py", line 669, in connect
    self._request_authentication()
  File "/mnt/c/Users/HP/neilla/frappe-bench/frappe-bench/env/lib/python3.12/site-packages/pymysql/connections.py", line 957, in _request_authentication
    auth_packet = self._read_packet()
                  ^^^^^^^^^^^^^^^^^^^
  File "/mnt/c/Users/HP/neilla/frappe-bench/frappe-bench/env/lib/python3.12/site-packages/pymysql/connections.py", line 775, in _read_packet
    packet.raise_for_error()
  File "/mnt/c/Users/HP/neilla/frappe-bench/frappe-bench/env/lib/python3.12/site-packages/pymysql/protocol.py", line 219, in raise_for_error
    err.raise_mysql_exception(self._data)
  File "/mnt/c/Users/HP/neilla/frappe-bench/frappe-bench/env/lib/python3.12/site-packages/pymysql/err.py", line 150, in raise_mysql_exception
    raise errorclass(errno, errval)
pymysql.err.OperationalError: (1049, "Unknown database '_cd931d51eba0e8ef'")
2025-04-18 02:18:06,499 ERROR scheduler Exception in Enqueue Events for Site emp.co.zw
Traceback (most recent call last):
  File "/mnt/c/Users/HP/neilla/frappe-bench/frappe-bench/apps/frappe/frappe/utils/scheduler.py", line 99, in enqueue_events_for_site
    if is_scheduler_inactive():
       ^^^^^^^^^^^^^^^^^^^^^^^
  File "/mnt/c/Users/HP/neilla/frappe-bench/frappe-bench/apps/frappe/frappe/utils/scheduler.py", line 143, in is_scheduler_inactive
    if is_scheduler_disabled(verbose=verbose):
       ^^^^^^^^^^^^^^^^^^^^^^^^^^^^^^^^^^^^^^
  File "/mnt/c/Users/HP/neilla/frappe-bench/frappe-bench/apps/frappe/frappe/utils/scheduler.py", line 156, in is_scheduler_disabled
    frappe.db.get_single_value("System Settings", "enable_scheduler")
  File "/mnt/c/Users/HP/neilla/frappe-bench/frappe-bench/apps/frappe/frappe/database/database.py", line 837, in get_single_value
    ).run()
      ^^^^^
  File "/mnt/c/Users/HP/neilla/frappe-bench/frappe-bench/apps/frappe/frappe/query_builder/utils.py", line 87, in execute_query
    result = frappe.db.sql(query, params, *args, **kwargs)  # nosemgrep
             ^^^^^^^^^^^^^^^^^^^^^^^^^^^^^^^^^^^^^^^^^^^^^
  File "/mnt/c/Users/HP/neilla/frappe-bench/frappe-bench/apps/frappe/frappe/database/database.py", line 207, in sql
    self.connect()
  File "/mnt/c/Users/HP/neilla/frappe-bench/frappe-bench/apps/frappe/frappe/database/database.py", line 112, in connect
    self._conn: "MariadbConnection" | "PostgresConnection" = self.get_connection()
                                                             ^^^^^^^^^^^^^^^^^^^^^
  File "/mnt/c/Users/HP/neilla/frappe-bench/frappe-bench/apps/frappe/frappe/database/mariadb/database.py", line 107, in get_connection
    conn = self._get_connection()
           ^^^^^^^^^^^^^^^^^^^^^^
  File "/mnt/c/Users/HP/neilla/frappe-bench/frappe-bench/apps/frappe/frappe/database/mariadb/database.py", line 113, in _get_connection
    return self.create_connection()
           ^^^^^^^^^^^^^^^^^^^^^^^^
  File "/mnt/c/Users/HP/neilla/frappe-bench/frappe-bench/apps/frappe/frappe/database/mariadb/database.py", line 116, in create_connection
    return pymysql.connect(**self.get_connection_settings())
           ^^^^^^^^^^^^^^^^^^^^^^^^^^^^^^^^^^^^^^^^^^^^^^^^^
  File "/mnt/c/Users/HP/neilla/frappe-bench/frappe-bench/env/lib/python3.12/site-packages/pymysql/connections.py", line 361, in __init__
    self.connect()
  File "/mnt/c/Users/HP/neilla/frappe-bench/frappe-bench/env/lib/python3.12/site-packages/pymysql/connections.py", line 669, in connect
    self._request_authentication()
  File "/mnt/c/Users/HP/neilla/frappe-bench/frappe-bench/env/lib/python3.12/site-packages/pymysql/connections.py", line 957, in _request_authentication
    auth_packet = self._read_packet()
                  ^^^^^^^^^^^^^^^^^^^
  File "/mnt/c/Users/HP/neilla/frappe-bench/frappe-bench/env/lib/python3.12/site-packages/pymysql/connections.py", line 775, in _read_packet
    packet.raise_for_error()
  File "/mnt/c/Users/HP/neilla/frappe-bench/frappe-bench/env/lib/python3.12/site-packages/pymysql/protocol.py", line 219, in raise_for_error
    err.raise_mysql_exception(self._data)
  File "/mnt/c/Users/HP/neilla/frappe-bench/frappe-bench/env/lib/python3.12/site-packages/pymysql/err.py", line 150, in raise_mysql_exception
    raise errorclass(errno, errval)
pymysql.err.OperationalError: (1049, "Unknown database '_cd931d51eba0e8ef'")
2025-04-18 02:19:06,590 ERROR scheduler Exception in Enqueue Events for Site emp.co.zw
Traceback (most recent call last):
  File "/mnt/c/Users/HP/neilla/frappe-bench/frappe-bench/apps/frappe/frappe/utils/scheduler.py", line 99, in enqueue_events_for_site
    if is_scheduler_inactive():
       ^^^^^^^^^^^^^^^^^^^^^^^
  File "/mnt/c/Users/HP/neilla/frappe-bench/frappe-bench/apps/frappe/frappe/utils/scheduler.py", line 143, in is_scheduler_inactive
    if is_scheduler_disabled(verbose=verbose):
       ^^^^^^^^^^^^^^^^^^^^^^^^^^^^^^^^^^^^^^
  File "/mnt/c/Users/HP/neilla/frappe-bench/frappe-bench/apps/frappe/frappe/utils/scheduler.py", line 156, in is_scheduler_disabled
    frappe.db.get_single_value("System Settings", "enable_scheduler")
  File "/mnt/c/Users/HP/neilla/frappe-bench/frappe-bench/apps/frappe/frappe/database/database.py", line 837, in get_single_value
    ).run()
      ^^^^^
  File "/mnt/c/Users/HP/neilla/frappe-bench/frappe-bench/apps/frappe/frappe/query_builder/utils.py", line 87, in execute_query
    result = frappe.db.sql(query, params, *args, **kwargs)  # nosemgrep
             ^^^^^^^^^^^^^^^^^^^^^^^^^^^^^^^^^^^^^^^^^^^^^
  File "/mnt/c/Users/HP/neilla/frappe-bench/frappe-bench/apps/frappe/frappe/database/database.py", line 207, in sql
    self.connect()
  File "/mnt/c/Users/HP/neilla/frappe-bench/frappe-bench/apps/frappe/frappe/database/database.py", line 112, in connect
    self._conn: "MariadbConnection" | "PostgresConnection" = self.get_connection()
                                                             ^^^^^^^^^^^^^^^^^^^^^
  File "/mnt/c/Users/HP/neilla/frappe-bench/frappe-bench/apps/frappe/frappe/database/mariadb/database.py", line 107, in get_connection
    conn = self._get_connection()
           ^^^^^^^^^^^^^^^^^^^^^^
  File "/mnt/c/Users/HP/neilla/frappe-bench/frappe-bench/apps/frappe/frappe/database/mariadb/database.py", line 113, in _get_connection
    return self.create_connection()
           ^^^^^^^^^^^^^^^^^^^^^^^^
  File "/mnt/c/Users/HP/neilla/frappe-bench/frappe-bench/apps/frappe/frappe/database/mariadb/database.py", line 116, in create_connection
    return pymysql.connect(**self.get_connection_settings())
           ^^^^^^^^^^^^^^^^^^^^^^^^^^^^^^^^^^^^^^^^^^^^^^^^^
  File "/mnt/c/Users/HP/neilla/frappe-bench/frappe-bench/env/lib/python3.12/site-packages/pymysql/connections.py", line 361, in __init__
    self.connect()
  File "/mnt/c/Users/HP/neilla/frappe-bench/frappe-bench/env/lib/python3.12/site-packages/pymysql/connections.py", line 669, in connect
    self._request_authentication()
  File "/mnt/c/Users/HP/neilla/frappe-bench/frappe-bench/env/lib/python3.12/site-packages/pymysql/connections.py", line 957, in _request_authentication
    auth_packet = self._read_packet()
                  ^^^^^^^^^^^^^^^^^^^
  File "/mnt/c/Users/HP/neilla/frappe-bench/frappe-bench/env/lib/python3.12/site-packages/pymysql/connections.py", line 775, in _read_packet
    packet.raise_for_error()
  File "/mnt/c/Users/HP/neilla/frappe-bench/frappe-bench/env/lib/python3.12/site-packages/pymysql/protocol.py", line 219, in raise_for_error
    err.raise_mysql_exception(self._data)
  File "/mnt/c/Users/HP/neilla/frappe-bench/frappe-bench/env/lib/python3.12/site-packages/pymysql/err.py", line 150, in raise_mysql_exception
    raise errorclass(errno, errval)
pymysql.err.OperationalError: (1049, "Unknown database '_cd931d51eba0e8ef'")
2025-04-18 02:20:06,718 ERROR scheduler Exception in Enqueue Events for Site emp.co.zw
Traceback (most recent call last):
  File "/mnt/c/Users/HP/neilla/frappe-bench/frappe-bench/apps/frappe/frappe/utils/scheduler.py", line 99, in enqueue_events_for_site
    if is_scheduler_inactive():
       ^^^^^^^^^^^^^^^^^^^^^^^
  File "/mnt/c/Users/HP/neilla/frappe-bench/frappe-bench/apps/frappe/frappe/utils/scheduler.py", line 143, in is_scheduler_inactive
    if is_scheduler_disabled(verbose=verbose):
       ^^^^^^^^^^^^^^^^^^^^^^^^^^^^^^^^^^^^^^
  File "/mnt/c/Users/HP/neilla/frappe-bench/frappe-bench/apps/frappe/frappe/utils/scheduler.py", line 156, in is_scheduler_disabled
    frappe.db.get_single_value("System Settings", "enable_scheduler")
  File "/mnt/c/Users/HP/neilla/frappe-bench/frappe-bench/apps/frappe/frappe/database/database.py", line 837, in get_single_value
    ).run()
      ^^^^^
  File "/mnt/c/Users/HP/neilla/frappe-bench/frappe-bench/apps/frappe/frappe/query_builder/utils.py", line 87, in execute_query
    result = frappe.db.sql(query, params, *args, **kwargs)  # nosemgrep
             ^^^^^^^^^^^^^^^^^^^^^^^^^^^^^^^^^^^^^^^^^^^^^
  File "/mnt/c/Users/HP/neilla/frappe-bench/frappe-bench/apps/frappe/frappe/database/database.py", line 207, in sql
    self.connect()
  File "/mnt/c/Users/HP/neilla/frappe-bench/frappe-bench/apps/frappe/frappe/database/database.py", line 112, in connect
    self._conn: "MariadbConnection" | "PostgresConnection" = self.get_connection()
                                                             ^^^^^^^^^^^^^^^^^^^^^
  File "/mnt/c/Users/HP/neilla/frappe-bench/frappe-bench/apps/frappe/frappe/database/mariadb/database.py", line 107, in get_connection
    conn = self._get_connection()
           ^^^^^^^^^^^^^^^^^^^^^^
  File "/mnt/c/Users/HP/neilla/frappe-bench/frappe-bench/apps/frappe/frappe/database/mariadb/database.py", line 113, in _get_connection
    return self.create_connection()
           ^^^^^^^^^^^^^^^^^^^^^^^^
  File "/mnt/c/Users/HP/neilla/frappe-bench/frappe-bench/apps/frappe/frappe/database/mariadb/database.py", line 116, in create_connection
    return pymysql.connect(**self.get_connection_settings())
           ^^^^^^^^^^^^^^^^^^^^^^^^^^^^^^^^^^^^^^^^^^^^^^^^^
  File "/mnt/c/Users/HP/neilla/frappe-bench/frappe-bench/env/lib/python3.12/site-packages/pymysql/connections.py", line 361, in __init__
    self.connect()
  File "/mnt/c/Users/HP/neilla/frappe-bench/frappe-bench/env/lib/python3.12/site-packages/pymysql/connections.py", line 669, in connect
    self._request_authentication()
  File "/mnt/c/Users/HP/neilla/frappe-bench/frappe-bench/env/lib/python3.12/site-packages/pymysql/connections.py", line 957, in _request_authentication
    auth_packet = self._read_packet()
                  ^^^^^^^^^^^^^^^^^^^
  File "/mnt/c/Users/HP/neilla/frappe-bench/frappe-bench/env/lib/python3.12/site-packages/pymysql/connections.py", line 775, in _read_packet
    packet.raise_for_error()
  File "/mnt/c/Users/HP/neilla/frappe-bench/frappe-bench/env/lib/python3.12/site-packages/pymysql/protocol.py", line 219, in raise_for_error
    err.raise_mysql_exception(self._data)
  File "/mnt/c/Users/HP/neilla/frappe-bench/frappe-bench/env/lib/python3.12/site-packages/pymysql/err.py", line 150, in raise_mysql_exception
    raise errorclass(errno, errval)
pymysql.err.OperationalError: (1049, "Unknown database '_cd931d51eba0e8ef'")
2025-04-18 02:21:06,808 ERROR scheduler Exception in Enqueue Events for Site emp.co.zw
Traceback (most recent call last):
  File "/mnt/c/Users/HP/neilla/frappe-bench/frappe-bench/apps/frappe/frappe/utils/scheduler.py", line 99, in enqueue_events_for_site
    if is_scheduler_inactive():
       ^^^^^^^^^^^^^^^^^^^^^^^
  File "/mnt/c/Users/HP/neilla/frappe-bench/frappe-bench/apps/frappe/frappe/utils/scheduler.py", line 143, in is_scheduler_inactive
    if is_scheduler_disabled(verbose=verbose):
       ^^^^^^^^^^^^^^^^^^^^^^^^^^^^^^^^^^^^^^
  File "/mnt/c/Users/HP/neilla/frappe-bench/frappe-bench/apps/frappe/frappe/utils/scheduler.py", line 156, in is_scheduler_disabled
    frappe.db.get_single_value("System Settings", "enable_scheduler")
  File "/mnt/c/Users/HP/neilla/frappe-bench/frappe-bench/apps/frappe/frappe/database/database.py", line 837, in get_single_value
    ).run()
      ^^^^^
  File "/mnt/c/Users/HP/neilla/frappe-bench/frappe-bench/apps/frappe/frappe/query_builder/utils.py", line 87, in execute_query
    result = frappe.db.sql(query, params, *args, **kwargs)  # nosemgrep
             ^^^^^^^^^^^^^^^^^^^^^^^^^^^^^^^^^^^^^^^^^^^^^
  File "/mnt/c/Users/HP/neilla/frappe-bench/frappe-bench/apps/frappe/frappe/database/database.py", line 207, in sql
    self.connect()
  File "/mnt/c/Users/HP/neilla/frappe-bench/frappe-bench/apps/frappe/frappe/database/database.py", line 112, in connect
    self._conn: "MariadbConnection" | "PostgresConnection" = self.get_connection()
                                                             ^^^^^^^^^^^^^^^^^^^^^
  File "/mnt/c/Users/HP/neilla/frappe-bench/frappe-bench/apps/frappe/frappe/database/mariadb/database.py", line 107, in get_connection
    conn = self._get_connection()
           ^^^^^^^^^^^^^^^^^^^^^^
  File "/mnt/c/Users/HP/neilla/frappe-bench/frappe-bench/apps/frappe/frappe/database/mariadb/database.py", line 113, in _get_connection
    return self.create_connection()
           ^^^^^^^^^^^^^^^^^^^^^^^^
  File "/mnt/c/Users/HP/neilla/frappe-bench/frappe-bench/apps/frappe/frappe/database/mariadb/database.py", line 116, in create_connection
    return pymysql.connect(**self.get_connection_settings())
           ^^^^^^^^^^^^^^^^^^^^^^^^^^^^^^^^^^^^^^^^^^^^^^^^^
  File "/mnt/c/Users/HP/neilla/frappe-bench/frappe-bench/env/lib/python3.12/site-packages/pymysql/connections.py", line 361, in __init__
    self.connect()
  File "/mnt/c/Users/HP/neilla/frappe-bench/frappe-bench/env/lib/python3.12/site-packages/pymysql/connections.py", line 669, in connect
    self._request_authentication()
  File "/mnt/c/Users/HP/neilla/frappe-bench/frappe-bench/env/lib/python3.12/site-packages/pymysql/connections.py", line 957, in _request_authentication
    auth_packet = self._read_packet()
                  ^^^^^^^^^^^^^^^^^^^
  File "/mnt/c/Users/HP/neilla/frappe-bench/frappe-bench/env/lib/python3.12/site-packages/pymysql/connections.py", line 775, in _read_packet
    packet.raise_for_error()
  File "/mnt/c/Users/HP/neilla/frappe-bench/frappe-bench/env/lib/python3.12/site-packages/pymysql/protocol.py", line 219, in raise_for_error
    err.raise_mysql_exception(self._data)
  File "/mnt/c/Users/HP/neilla/frappe-bench/frappe-bench/env/lib/python3.12/site-packages/pymysql/err.py", line 150, in raise_mysql_exception
    raise errorclass(errno, errval)
pymysql.err.OperationalError: (1049, "Unknown database '_cd931d51eba0e8ef'")
2025-04-18 02:22:06,885 ERROR scheduler Exception in Enqueue Events for Site emp.co.zw
Traceback (most recent call last):
  File "/mnt/c/Users/HP/neilla/frappe-bench/frappe-bench/apps/frappe/frappe/utils/scheduler.py", line 99, in enqueue_events_for_site
    if is_scheduler_inactive():
       ^^^^^^^^^^^^^^^^^^^^^^^
  File "/mnt/c/Users/HP/neilla/frappe-bench/frappe-bench/apps/frappe/frappe/utils/scheduler.py", line 143, in is_scheduler_inactive
    if is_scheduler_disabled(verbose=verbose):
       ^^^^^^^^^^^^^^^^^^^^^^^^^^^^^^^^^^^^^^
  File "/mnt/c/Users/HP/neilla/frappe-bench/frappe-bench/apps/frappe/frappe/utils/scheduler.py", line 156, in is_scheduler_disabled
    frappe.db.get_single_value("System Settings", "enable_scheduler")
  File "/mnt/c/Users/HP/neilla/frappe-bench/frappe-bench/apps/frappe/frappe/database/database.py", line 837, in get_single_value
    ).run()
      ^^^^^
  File "/mnt/c/Users/HP/neilla/frappe-bench/frappe-bench/apps/frappe/frappe/query_builder/utils.py", line 87, in execute_query
    result = frappe.db.sql(query, params, *args, **kwargs)  # nosemgrep
             ^^^^^^^^^^^^^^^^^^^^^^^^^^^^^^^^^^^^^^^^^^^^^
  File "/mnt/c/Users/HP/neilla/frappe-bench/frappe-bench/apps/frappe/frappe/database/database.py", line 207, in sql
    self.connect()
  File "/mnt/c/Users/HP/neilla/frappe-bench/frappe-bench/apps/frappe/frappe/database/database.py", line 112, in connect
    self._conn: "MariadbConnection" | "PostgresConnection" = self.get_connection()
                                                             ^^^^^^^^^^^^^^^^^^^^^
  File "/mnt/c/Users/HP/neilla/frappe-bench/frappe-bench/apps/frappe/frappe/database/mariadb/database.py", line 107, in get_connection
    conn = self._get_connection()
           ^^^^^^^^^^^^^^^^^^^^^^
  File "/mnt/c/Users/HP/neilla/frappe-bench/frappe-bench/apps/frappe/frappe/database/mariadb/database.py", line 113, in _get_connection
    return self.create_connection()
           ^^^^^^^^^^^^^^^^^^^^^^^^
  File "/mnt/c/Users/HP/neilla/frappe-bench/frappe-bench/apps/frappe/frappe/database/mariadb/database.py", line 116, in create_connection
    return pymysql.connect(**self.get_connection_settings())
           ^^^^^^^^^^^^^^^^^^^^^^^^^^^^^^^^^^^^^^^^^^^^^^^^^
  File "/mnt/c/Users/HP/neilla/frappe-bench/frappe-bench/env/lib/python3.12/site-packages/pymysql/connections.py", line 361, in __init__
    self.connect()
  File "/mnt/c/Users/HP/neilla/frappe-bench/frappe-bench/env/lib/python3.12/site-packages/pymysql/connections.py", line 669, in connect
    self._request_authentication()
  File "/mnt/c/Users/HP/neilla/frappe-bench/frappe-bench/env/lib/python3.12/site-packages/pymysql/connections.py", line 957, in _request_authentication
    auth_packet = self._read_packet()
                  ^^^^^^^^^^^^^^^^^^^
  File "/mnt/c/Users/HP/neilla/frappe-bench/frappe-bench/env/lib/python3.12/site-packages/pymysql/connections.py", line 775, in _read_packet
    packet.raise_for_error()
  File "/mnt/c/Users/HP/neilla/frappe-bench/frappe-bench/env/lib/python3.12/site-packages/pymysql/protocol.py", line 219, in raise_for_error
    err.raise_mysql_exception(self._data)
  File "/mnt/c/Users/HP/neilla/frappe-bench/frappe-bench/env/lib/python3.12/site-packages/pymysql/err.py", line 150, in raise_mysql_exception
    raise errorclass(errno, errval)
pymysql.err.OperationalError: (1049, "Unknown database '_cd931d51eba0e8ef'")
2025-04-18 02:23:06,978 ERROR scheduler Exception in Enqueue Events for Site emp.co.zw
Traceback (most recent call last):
  File "/mnt/c/Users/HP/neilla/frappe-bench/frappe-bench/apps/frappe/frappe/utils/scheduler.py", line 99, in enqueue_events_for_site
    if is_scheduler_inactive():
       ^^^^^^^^^^^^^^^^^^^^^^^
  File "/mnt/c/Users/HP/neilla/frappe-bench/frappe-bench/apps/frappe/frappe/utils/scheduler.py", line 143, in is_scheduler_inactive
    if is_scheduler_disabled(verbose=verbose):
       ^^^^^^^^^^^^^^^^^^^^^^^^^^^^^^^^^^^^^^
  File "/mnt/c/Users/HP/neilla/frappe-bench/frappe-bench/apps/frappe/frappe/utils/scheduler.py", line 156, in is_scheduler_disabled
    frappe.db.get_single_value("System Settings", "enable_scheduler")
  File "/mnt/c/Users/HP/neilla/frappe-bench/frappe-bench/apps/frappe/frappe/database/database.py", line 837, in get_single_value
    ).run()
      ^^^^^
  File "/mnt/c/Users/HP/neilla/frappe-bench/frappe-bench/apps/frappe/frappe/query_builder/utils.py", line 87, in execute_query
    result = frappe.db.sql(query, params, *args, **kwargs)  # nosemgrep
             ^^^^^^^^^^^^^^^^^^^^^^^^^^^^^^^^^^^^^^^^^^^^^
  File "/mnt/c/Users/HP/neilla/frappe-bench/frappe-bench/apps/frappe/frappe/database/database.py", line 207, in sql
    self.connect()
  File "/mnt/c/Users/HP/neilla/frappe-bench/frappe-bench/apps/frappe/frappe/database/database.py", line 112, in connect
    self._conn: "MariadbConnection" | "PostgresConnection" = self.get_connection()
                                                             ^^^^^^^^^^^^^^^^^^^^^
  File "/mnt/c/Users/HP/neilla/frappe-bench/frappe-bench/apps/frappe/frappe/database/mariadb/database.py", line 107, in get_connection
    conn = self._get_connection()
           ^^^^^^^^^^^^^^^^^^^^^^
  File "/mnt/c/Users/HP/neilla/frappe-bench/frappe-bench/apps/frappe/frappe/database/mariadb/database.py", line 113, in _get_connection
    return self.create_connection()
           ^^^^^^^^^^^^^^^^^^^^^^^^
  File "/mnt/c/Users/HP/neilla/frappe-bench/frappe-bench/apps/frappe/frappe/database/mariadb/database.py", line 116, in create_connection
    return pymysql.connect(**self.get_connection_settings())
           ^^^^^^^^^^^^^^^^^^^^^^^^^^^^^^^^^^^^^^^^^^^^^^^^^
  File "/mnt/c/Users/HP/neilla/frappe-bench/frappe-bench/env/lib/python3.12/site-packages/pymysql/connections.py", line 361, in __init__
    self.connect()
  File "/mnt/c/Users/HP/neilla/frappe-bench/frappe-bench/env/lib/python3.12/site-packages/pymysql/connections.py", line 669, in connect
    self._request_authentication()
  File "/mnt/c/Users/HP/neilla/frappe-bench/frappe-bench/env/lib/python3.12/site-packages/pymysql/connections.py", line 957, in _request_authentication
    auth_packet = self._read_packet()
                  ^^^^^^^^^^^^^^^^^^^
  File "/mnt/c/Users/HP/neilla/frappe-bench/frappe-bench/env/lib/python3.12/site-packages/pymysql/connections.py", line 775, in _read_packet
    packet.raise_for_error()
  File "/mnt/c/Users/HP/neilla/frappe-bench/frappe-bench/env/lib/python3.12/site-packages/pymysql/protocol.py", line 219, in raise_for_error
    err.raise_mysql_exception(self._data)
  File "/mnt/c/Users/HP/neilla/frappe-bench/frappe-bench/env/lib/python3.12/site-packages/pymysql/err.py", line 150, in raise_mysql_exception
    raise errorclass(errno, errval)
pymysql.err.OperationalError: (1049, "Unknown database '_cd931d51eba0e8ef'")
2025-04-18 02:24:07,110 ERROR scheduler Exception in Enqueue Events for Site emp.co.zw
Traceback (most recent call last):
  File "/mnt/c/Users/HP/neilla/frappe-bench/frappe-bench/apps/frappe/frappe/utils/scheduler.py", line 99, in enqueue_events_for_site
    if is_scheduler_inactive():
       ^^^^^^^^^^^^^^^^^^^^^^^
  File "/mnt/c/Users/HP/neilla/frappe-bench/frappe-bench/apps/frappe/frappe/utils/scheduler.py", line 143, in is_scheduler_inactive
    if is_scheduler_disabled(verbose=verbose):
       ^^^^^^^^^^^^^^^^^^^^^^^^^^^^^^^^^^^^^^
  File "/mnt/c/Users/HP/neilla/frappe-bench/frappe-bench/apps/frappe/frappe/utils/scheduler.py", line 156, in is_scheduler_disabled
    frappe.db.get_single_value("System Settings", "enable_scheduler")
  File "/mnt/c/Users/HP/neilla/frappe-bench/frappe-bench/apps/frappe/frappe/database/database.py", line 837, in get_single_value
    ).run()
      ^^^^^
  File "/mnt/c/Users/HP/neilla/frappe-bench/frappe-bench/apps/frappe/frappe/query_builder/utils.py", line 87, in execute_query
    result = frappe.db.sql(query, params, *args, **kwargs)  # nosemgrep
             ^^^^^^^^^^^^^^^^^^^^^^^^^^^^^^^^^^^^^^^^^^^^^
  File "/mnt/c/Users/HP/neilla/frappe-bench/frappe-bench/apps/frappe/frappe/database/database.py", line 207, in sql
    self.connect()
  File "/mnt/c/Users/HP/neilla/frappe-bench/frappe-bench/apps/frappe/frappe/database/database.py", line 112, in connect
    self._conn: "MariadbConnection" | "PostgresConnection" = self.get_connection()
                                                             ^^^^^^^^^^^^^^^^^^^^^
  File "/mnt/c/Users/HP/neilla/frappe-bench/frappe-bench/apps/frappe/frappe/database/mariadb/database.py", line 107, in get_connection
    conn = self._get_connection()
           ^^^^^^^^^^^^^^^^^^^^^^
  File "/mnt/c/Users/HP/neilla/frappe-bench/frappe-bench/apps/frappe/frappe/database/mariadb/database.py", line 113, in _get_connection
    return self.create_connection()
           ^^^^^^^^^^^^^^^^^^^^^^^^
  File "/mnt/c/Users/HP/neilla/frappe-bench/frappe-bench/apps/frappe/frappe/database/mariadb/database.py", line 116, in create_connection
    return pymysql.connect(**self.get_connection_settings())
           ^^^^^^^^^^^^^^^^^^^^^^^^^^^^^^^^^^^^^^^^^^^^^^^^^
  File "/mnt/c/Users/HP/neilla/frappe-bench/frappe-bench/env/lib/python3.12/site-packages/pymysql/connections.py", line 361, in __init__
    self.connect()
  File "/mnt/c/Users/HP/neilla/frappe-bench/frappe-bench/env/lib/python3.12/site-packages/pymysql/connections.py", line 669, in connect
    self._request_authentication()
  File "/mnt/c/Users/HP/neilla/frappe-bench/frappe-bench/env/lib/python3.12/site-packages/pymysql/connections.py", line 957, in _request_authentication
    auth_packet = self._read_packet()
                  ^^^^^^^^^^^^^^^^^^^
  File "/mnt/c/Users/HP/neilla/frappe-bench/frappe-bench/env/lib/python3.12/site-packages/pymysql/connections.py", line 775, in _read_packet
    packet.raise_for_error()
  File "/mnt/c/Users/HP/neilla/frappe-bench/frappe-bench/env/lib/python3.12/site-packages/pymysql/protocol.py", line 219, in raise_for_error
    err.raise_mysql_exception(self._data)
  File "/mnt/c/Users/HP/neilla/frappe-bench/frappe-bench/env/lib/python3.12/site-packages/pymysql/err.py", line 150, in raise_mysql_exception
    raise errorclass(errno, errval)
pymysql.err.OperationalError: (1049, "Unknown database '_cd931d51eba0e8ef'")
2025-04-18 02:25:07,191 ERROR scheduler Exception in Enqueue Events for Site emp.co.zw
Traceback (most recent call last):
  File "/mnt/c/Users/HP/neilla/frappe-bench/frappe-bench/apps/frappe/frappe/utils/scheduler.py", line 99, in enqueue_events_for_site
    if is_scheduler_inactive():
       ^^^^^^^^^^^^^^^^^^^^^^^
  File "/mnt/c/Users/HP/neilla/frappe-bench/frappe-bench/apps/frappe/frappe/utils/scheduler.py", line 143, in is_scheduler_inactive
    if is_scheduler_disabled(verbose=verbose):
       ^^^^^^^^^^^^^^^^^^^^^^^^^^^^^^^^^^^^^^
  File "/mnt/c/Users/HP/neilla/frappe-bench/frappe-bench/apps/frappe/frappe/utils/scheduler.py", line 156, in is_scheduler_disabled
    frappe.db.get_single_value("System Settings", "enable_scheduler")
  File "/mnt/c/Users/HP/neilla/frappe-bench/frappe-bench/apps/frappe/frappe/database/database.py", line 837, in get_single_value
    ).run()
      ^^^^^
  File "/mnt/c/Users/HP/neilla/frappe-bench/frappe-bench/apps/frappe/frappe/query_builder/utils.py", line 87, in execute_query
    result = frappe.db.sql(query, params, *args, **kwargs)  # nosemgrep
             ^^^^^^^^^^^^^^^^^^^^^^^^^^^^^^^^^^^^^^^^^^^^^
  File "/mnt/c/Users/HP/neilla/frappe-bench/frappe-bench/apps/frappe/frappe/database/database.py", line 207, in sql
    self.connect()
  File "/mnt/c/Users/HP/neilla/frappe-bench/frappe-bench/apps/frappe/frappe/database/database.py", line 112, in connect
    self._conn: "MariadbConnection" | "PostgresConnection" = self.get_connection()
                                                             ^^^^^^^^^^^^^^^^^^^^^
  File "/mnt/c/Users/HP/neilla/frappe-bench/frappe-bench/apps/frappe/frappe/database/mariadb/database.py", line 107, in get_connection
    conn = self._get_connection()
           ^^^^^^^^^^^^^^^^^^^^^^
  File "/mnt/c/Users/HP/neilla/frappe-bench/frappe-bench/apps/frappe/frappe/database/mariadb/database.py", line 113, in _get_connection
    return self.create_connection()
           ^^^^^^^^^^^^^^^^^^^^^^^^
  File "/mnt/c/Users/HP/neilla/frappe-bench/frappe-bench/apps/frappe/frappe/database/mariadb/database.py", line 116, in create_connection
    return pymysql.connect(**self.get_connection_settings())
           ^^^^^^^^^^^^^^^^^^^^^^^^^^^^^^^^^^^^^^^^^^^^^^^^^
  File "/mnt/c/Users/HP/neilla/frappe-bench/frappe-bench/env/lib/python3.12/site-packages/pymysql/connections.py", line 361, in __init__
    self.connect()
  File "/mnt/c/Users/HP/neilla/frappe-bench/frappe-bench/env/lib/python3.12/site-packages/pymysql/connections.py", line 669, in connect
    self._request_authentication()
  File "/mnt/c/Users/HP/neilla/frappe-bench/frappe-bench/env/lib/python3.12/site-packages/pymysql/connections.py", line 957, in _request_authentication
    auth_packet = self._read_packet()
                  ^^^^^^^^^^^^^^^^^^^
  File "/mnt/c/Users/HP/neilla/frappe-bench/frappe-bench/env/lib/python3.12/site-packages/pymysql/connections.py", line 775, in _read_packet
    packet.raise_for_error()
  File "/mnt/c/Users/HP/neilla/frappe-bench/frappe-bench/env/lib/python3.12/site-packages/pymysql/protocol.py", line 219, in raise_for_error
    err.raise_mysql_exception(self._data)
  File "/mnt/c/Users/HP/neilla/frappe-bench/frappe-bench/env/lib/python3.12/site-packages/pymysql/err.py", line 150, in raise_mysql_exception
    raise errorclass(errno, errval)
pymysql.err.OperationalError: (1049, "Unknown database '_cd931d51eba0e8ef'")
2025-04-18 02:26:07,288 ERROR scheduler Exception in Enqueue Events for Site emp.co.zw
Traceback (most recent call last):
  File "/mnt/c/Users/HP/neilla/frappe-bench/frappe-bench/apps/frappe/frappe/utils/scheduler.py", line 99, in enqueue_events_for_site
    if is_scheduler_inactive():
       ^^^^^^^^^^^^^^^^^^^^^^^
  File "/mnt/c/Users/HP/neilla/frappe-bench/frappe-bench/apps/frappe/frappe/utils/scheduler.py", line 143, in is_scheduler_inactive
    if is_scheduler_disabled(verbose=verbose):
       ^^^^^^^^^^^^^^^^^^^^^^^^^^^^^^^^^^^^^^
  File "/mnt/c/Users/HP/neilla/frappe-bench/frappe-bench/apps/frappe/frappe/utils/scheduler.py", line 156, in is_scheduler_disabled
    frappe.db.get_single_value("System Settings", "enable_scheduler")
  File "/mnt/c/Users/HP/neilla/frappe-bench/frappe-bench/apps/frappe/frappe/database/database.py", line 837, in get_single_value
    ).run()
      ^^^^^
  File "/mnt/c/Users/HP/neilla/frappe-bench/frappe-bench/apps/frappe/frappe/query_builder/utils.py", line 87, in execute_query
    result = frappe.db.sql(query, params, *args, **kwargs)  # nosemgrep
             ^^^^^^^^^^^^^^^^^^^^^^^^^^^^^^^^^^^^^^^^^^^^^
  File "/mnt/c/Users/HP/neilla/frappe-bench/frappe-bench/apps/frappe/frappe/database/database.py", line 207, in sql
    self.connect()
  File "/mnt/c/Users/HP/neilla/frappe-bench/frappe-bench/apps/frappe/frappe/database/database.py", line 112, in connect
    self._conn: "MariadbConnection" | "PostgresConnection" = self.get_connection()
                                                             ^^^^^^^^^^^^^^^^^^^^^
  File "/mnt/c/Users/HP/neilla/frappe-bench/frappe-bench/apps/frappe/frappe/database/mariadb/database.py", line 107, in get_connection
    conn = self._get_connection()
           ^^^^^^^^^^^^^^^^^^^^^^
  File "/mnt/c/Users/HP/neilla/frappe-bench/frappe-bench/apps/frappe/frappe/database/mariadb/database.py", line 113, in _get_connection
    return self.create_connection()
           ^^^^^^^^^^^^^^^^^^^^^^^^
  File "/mnt/c/Users/HP/neilla/frappe-bench/frappe-bench/apps/frappe/frappe/database/mariadb/database.py", line 116, in create_connection
    return pymysql.connect(**self.get_connection_settings())
           ^^^^^^^^^^^^^^^^^^^^^^^^^^^^^^^^^^^^^^^^^^^^^^^^^
  File "/mnt/c/Users/HP/neilla/frappe-bench/frappe-bench/env/lib/python3.12/site-packages/pymysql/connections.py", line 361, in __init__
    self.connect()
  File "/mnt/c/Users/HP/neilla/frappe-bench/frappe-bench/env/lib/python3.12/site-packages/pymysql/connections.py", line 669, in connect
    self._request_authentication()
  File "/mnt/c/Users/HP/neilla/frappe-bench/frappe-bench/env/lib/python3.12/site-packages/pymysql/connections.py", line 957, in _request_authentication
    auth_packet = self._read_packet()
                  ^^^^^^^^^^^^^^^^^^^
  File "/mnt/c/Users/HP/neilla/frappe-bench/frappe-bench/env/lib/python3.12/site-packages/pymysql/connections.py", line 775, in _read_packet
    packet.raise_for_error()
  File "/mnt/c/Users/HP/neilla/frappe-bench/frappe-bench/env/lib/python3.12/site-packages/pymysql/protocol.py", line 219, in raise_for_error
    err.raise_mysql_exception(self._data)
  File "/mnt/c/Users/HP/neilla/frappe-bench/frappe-bench/env/lib/python3.12/site-packages/pymysql/err.py", line 150, in raise_mysql_exception
    raise errorclass(errno, errval)
pymysql.err.OperationalError: (1049, "Unknown database '_cd931d51eba0e8ef'")
2025-04-18 02:27:07,371 ERROR scheduler Exception in Enqueue Events for Site emp.co.zw
Traceback (most recent call last):
  File "/mnt/c/Users/HP/neilla/frappe-bench/frappe-bench/apps/frappe/frappe/utils/scheduler.py", line 99, in enqueue_events_for_site
    if is_scheduler_inactive():
       ^^^^^^^^^^^^^^^^^^^^^^^
  File "/mnt/c/Users/HP/neilla/frappe-bench/frappe-bench/apps/frappe/frappe/utils/scheduler.py", line 143, in is_scheduler_inactive
    if is_scheduler_disabled(verbose=verbose):
       ^^^^^^^^^^^^^^^^^^^^^^^^^^^^^^^^^^^^^^
  File "/mnt/c/Users/HP/neilla/frappe-bench/frappe-bench/apps/frappe/frappe/utils/scheduler.py", line 156, in is_scheduler_disabled
    frappe.db.get_single_value("System Settings", "enable_scheduler")
  File "/mnt/c/Users/HP/neilla/frappe-bench/frappe-bench/apps/frappe/frappe/database/database.py", line 837, in get_single_value
    ).run()
      ^^^^^
  File "/mnt/c/Users/HP/neilla/frappe-bench/frappe-bench/apps/frappe/frappe/query_builder/utils.py", line 87, in execute_query
    result = frappe.db.sql(query, params, *args, **kwargs)  # nosemgrep
             ^^^^^^^^^^^^^^^^^^^^^^^^^^^^^^^^^^^^^^^^^^^^^
  File "/mnt/c/Users/HP/neilla/frappe-bench/frappe-bench/apps/frappe/frappe/database/database.py", line 207, in sql
    self.connect()
  File "/mnt/c/Users/HP/neilla/frappe-bench/frappe-bench/apps/frappe/frappe/database/database.py", line 112, in connect
    self._conn: "MariadbConnection" | "PostgresConnection" = self.get_connection()
                                                             ^^^^^^^^^^^^^^^^^^^^^
  File "/mnt/c/Users/HP/neilla/frappe-bench/frappe-bench/apps/frappe/frappe/database/mariadb/database.py", line 107, in get_connection
    conn = self._get_connection()
           ^^^^^^^^^^^^^^^^^^^^^^
  File "/mnt/c/Users/HP/neilla/frappe-bench/frappe-bench/apps/frappe/frappe/database/mariadb/database.py", line 113, in _get_connection
    return self.create_connection()
           ^^^^^^^^^^^^^^^^^^^^^^^^
  File "/mnt/c/Users/HP/neilla/frappe-bench/frappe-bench/apps/frappe/frappe/database/mariadb/database.py", line 116, in create_connection
    return pymysql.connect(**self.get_connection_settings())
           ^^^^^^^^^^^^^^^^^^^^^^^^^^^^^^^^^^^^^^^^^^^^^^^^^
  File "/mnt/c/Users/HP/neilla/frappe-bench/frappe-bench/env/lib/python3.12/site-packages/pymysql/connections.py", line 361, in __init__
    self.connect()
  File "/mnt/c/Users/HP/neilla/frappe-bench/frappe-bench/env/lib/python3.12/site-packages/pymysql/connections.py", line 669, in connect
    self._request_authentication()
  File "/mnt/c/Users/HP/neilla/frappe-bench/frappe-bench/env/lib/python3.12/site-packages/pymysql/connections.py", line 957, in _request_authentication
    auth_packet = self._read_packet()
                  ^^^^^^^^^^^^^^^^^^^
  File "/mnt/c/Users/HP/neilla/frappe-bench/frappe-bench/env/lib/python3.12/site-packages/pymysql/connections.py", line 775, in _read_packet
    packet.raise_for_error()
  File "/mnt/c/Users/HP/neilla/frappe-bench/frappe-bench/env/lib/python3.12/site-packages/pymysql/protocol.py", line 219, in raise_for_error
    err.raise_mysql_exception(self._data)
  File "/mnt/c/Users/HP/neilla/frappe-bench/frappe-bench/env/lib/python3.12/site-packages/pymysql/err.py", line 150, in raise_mysql_exception
    raise errorclass(errno, errval)
pymysql.err.OperationalError: (1049, "Unknown database '_cd931d51eba0e8ef'")
2025-04-18 02:28:07,447 ERROR scheduler Exception in Enqueue Events for Site emp.co.zw
Traceback (most recent call last):
  File "/mnt/c/Users/HP/neilla/frappe-bench/frappe-bench/apps/frappe/frappe/utils/scheduler.py", line 99, in enqueue_events_for_site
    if is_scheduler_inactive():
       ^^^^^^^^^^^^^^^^^^^^^^^
  File "/mnt/c/Users/HP/neilla/frappe-bench/frappe-bench/apps/frappe/frappe/utils/scheduler.py", line 143, in is_scheduler_inactive
    if is_scheduler_disabled(verbose=verbose):
       ^^^^^^^^^^^^^^^^^^^^^^^^^^^^^^^^^^^^^^
  File "/mnt/c/Users/HP/neilla/frappe-bench/frappe-bench/apps/frappe/frappe/utils/scheduler.py", line 156, in is_scheduler_disabled
    frappe.db.get_single_value("System Settings", "enable_scheduler")
  File "/mnt/c/Users/HP/neilla/frappe-bench/frappe-bench/apps/frappe/frappe/database/database.py", line 837, in get_single_value
    ).run()
      ^^^^^
  File "/mnt/c/Users/HP/neilla/frappe-bench/frappe-bench/apps/frappe/frappe/query_builder/utils.py", line 87, in execute_query
    result = frappe.db.sql(query, params, *args, **kwargs)  # nosemgrep
             ^^^^^^^^^^^^^^^^^^^^^^^^^^^^^^^^^^^^^^^^^^^^^
  File "/mnt/c/Users/HP/neilla/frappe-bench/frappe-bench/apps/frappe/frappe/database/database.py", line 207, in sql
    self.connect()
  File "/mnt/c/Users/HP/neilla/frappe-bench/frappe-bench/apps/frappe/frappe/database/database.py", line 112, in connect
    self._conn: "MariadbConnection" | "PostgresConnection" = self.get_connection()
                                                             ^^^^^^^^^^^^^^^^^^^^^
  File "/mnt/c/Users/HP/neilla/frappe-bench/frappe-bench/apps/frappe/frappe/database/mariadb/database.py", line 107, in get_connection
    conn = self._get_connection()
           ^^^^^^^^^^^^^^^^^^^^^^
  File "/mnt/c/Users/HP/neilla/frappe-bench/frappe-bench/apps/frappe/frappe/database/mariadb/database.py", line 113, in _get_connection
    return self.create_connection()
           ^^^^^^^^^^^^^^^^^^^^^^^^
  File "/mnt/c/Users/HP/neilla/frappe-bench/frappe-bench/apps/frappe/frappe/database/mariadb/database.py", line 116, in create_connection
    return pymysql.connect(**self.get_connection_settings())
           ^^^^^^^^^^^^^^^^^^^^^^^^^^^^^^^^^^^^^^^^^^^^^^^^^
  File "/mnt/c/Users/HP/neilla/frappe-bench/frappe-bench/env/lib/python3.12/site-packages/pymysql/connections.py", line 361, in __init__
    self.connect()
  File "/mnt/c/Users/HP/neilla/frappe-bench/frappe-bench/env/lib/python3.12/site-packages/pymysql/connections.py", line 669, in connect
    self._request_authentication()
  File "/mnt/c/Users/HP/neilla/frappe-bench/frappe-bench/env/lib/python3.12/site-packages/pymysql/connections.py", line 957, in _request_authentication
    auth_packet = self._read_packet()
                  ^^^^^^^^^^^^^^^^^^^
  File "/mnt/c/Users/HP/neilla/frappe-bench/frappe-bench/env/lib/python3.12/site-packages/pymysql/connections.py", line 775, in _read_packet
    packet.raise_for_error()
  File "/mnt/c/Users/HP/neilla/frappe-bench/frappe-bench/env/lib/python3.12/site-packages/pymysql/protocol.py", line 219, in raise_for_error
    err.raise_mysql_exception(self._data)
  File "/mnt/c/Users/HP/neilla/frappe-bench/frappe-bench/env/lib/python3.12/site-packages/pymysql/err.py", line 150, in raise_mysql_exception
    raise errorclass(errno, errval)
pymysql.err.OperationalError: (1049, "Unknown database '_cd931d51eba0e8ef'")
2025-04-18 02:29:07,564 ERROR scheduler Exception in Enqueue Events for Site emp.co.zw
Traceback (most recent call last):
  File "/mnt/c/Users/HP/neilla/frappe-bench/frappe-bench/apps/frappe/frappe/utils/scheduler.py", line 99, in enqueue_events_for_site
    if is_scheduler_inactive():
       ^^^^^^^^^^^^^^^^^^^^^^^
  File "/mnt/c/Users/HP/neilla/frappe-bench/frappe-bench/apps/frappe/frappe/utils/scheduler.py", line 143, in is_scheduler_inactive
    if is_scheduler_disabled(verbose=verbose):
       ^^^^^^^^^^^^^^^^^^^^^^^^^^^^^^^^^^^^^^
  File "/mnt/c/Users/HP/neilla/frappe-bench/frappe-bench/apps/frappe/frappe/utils/scheduler.py", line 156, in is_scheduler_disabled
    frappe.db.get_single_value("System Settings", "enable_scheduler")
  File "/mnt/c/Users/HP/neilla/frappe-bench/frappe-bench/apps/frappe/frappe/database/database.py", line 837, in get_single_value
    ).run()
      ^^^^^
  File "/mnt/c/Users/HP/neilla/frappe-bench/frappe-bench/apps/frappe/frappe/query_builder/utils.py", line 87, in execute_query
    result = frappe.db.sql(query, params, *args, **kwargs)  # nosemgrep
             ^^^^^^^^^^^^^^^^^^^^^^^^^^^^^^^^^^^^^^^^^^^^^
  File "/mnt/c/Users/HP/neilla/frappe-bench/frappe-bench/apps/frappe/frappe/database/database.py", line 207, in sql
    self.connect()
  File "/mnt/c/Users/HP/neilla/frappe-bench/frappe-bench/apps/frappe/frappe/database/database.py", line 112, in connect
    self._conn: "MariadbConnection" | "PostgresConnection" = self.get_connection()
                                                             ^^^^^^^^^^^^^^^^^^^^^
  File "/mnt/c/Users/HP/neilla/frappe-bench/frappe-bench/apps/frappe/frappe/database/mariadb/database.py", line 107, in get_connection
    conn = self._get_connection()
           ^^^^^^^^^^^^^^^^^^^^^^
  File "/mnt/c/Users/HP/neilla/frappe-bench/frappe-bench/apps/frappe/frappe/database/mariadb/database.py", line 113, in _get_connection
    return self.create_connection()
           ^^^^^^^^^^^^^^^^^^^^^^^^
  File "/mnt/c/Users/HP/neilla/frappe-bench/frappe-bench/apps/frappe/frappe/database/mariadb/database.py", line 116, in create_connection
    return pymysql.connect(**self.get_connection_settings())
           ^^^^^^^^^^^^^^^^^^^^^^^^^^^^^^^^^^^^^^^^^^^^^^^^^
  File "/mnt/c/Users/HP/neilla/frappe-bench/frappe-bench/env/lib/python3.12/site-packages/pymysql/connections.py", line 361, in __init__
    self.connect()
  File "/mnt/c/Users/HP/neilla/frappe-bench/frappe-bench/env/lib/python3.12/site-packages/pymysql/connections.py", line 669, in connect
    self._request_authentication()
  File "/mnt/c/Users/HP/neilla/frappe-bench/frappe-bench/env/lib/python3.12/site-packages/pymysql/connections.py", line 957, in _request_authentication
    auth_packet = self._read_packet()
                  ^^^^^^^^^^^^^^^^^^^
  File "/mnt/c/Users/HP/neilla/frappe-bench/frappe-bench/env/lib/python3.12/site-packages/pymysql/connections.py", line 775, in _read_packet
    packet.raise_for_error()
  File "/mnt/c/Users/HP/neilla/frappe-bench/frappe-bench/env/lib/python3.12/site-packages/pymysql/protocol.py", line 219, in raise_for_error
    err.raise_mysql_exception(self._data)
  File "/mnt/c/Users/HP/neilla/frappe-bench/frappe-bench/env/lib/python3.12/site-packages/pymysql/err.py", line 150, in raise_mysql_exception
    raise errorclass(errno, errval)
pymysql.err.OperationalError: (1049, "Unknown database '_cd931d51eba0e8ef'")
2025-04-18 02:30:07,717 ERROR scheduler Exception in Enqueue Events for Site emp.co.zw
Traceback (most recent call last):
  File "/mnt/c/Users/HP/neilla/frappe-bench/frappe-bench/apps/frappe/frappe/utils/scheduler.py", line 99, in enqueue_events_for_site
    if is_scheduler_inactive():
       ^^^^^^^^^^^^^^^^^^^^^^^
  File "/mnt/c/Users/HP/neilla/frappe-bench/frappe-bench/apps/frappe/frappe/utils/scheduler.py", line 143, in is_scheduler_inactive
    if is_scheduler_disabled(verbose=verbose):
       ^^^^^^^^^^^^^^^^^^^^^^^^^^^^^^^^^^^^^^
  File "/mnt/c/Users/HP/neilla/frappe-bench/frappe-bench/apps/frappe/frappe/utils/scheduler.py", line 156, in is_scheduler_disabled
    frappe.db.get_single_value("System Settings", "enable_scheduler")
  File "/mnt/c/Users/HP/neilla/frappe-bench/frappe-bench/apps/frappe/frappe/database/database.py", line 837, in get_single_value
    ).run()
      ^^^^^
  File "/mnt/c/Users/HP/neilla/frappe-bench/frappe-bench/apps/frappe/frappe/query_builder/utils.py", line 87, in execute_query
    result = frappe.db.sql(query, params, *args, **kwargs)  # nosemgrep
             ^^^^^^^^^^^^^^^^^^^^^^^^^^^^^^^^^^^^^^^^^^^^^
  File "/mnt/c/Users/HP/neilla/frappe-bench/frappe-bench/apps/frappe/frappe/database/database.py", line 207, in sql
    self.connect()
  File "/mnt/c/Users/HP/neilla/frappe-bench/frappe-bench/apps/frappe/frappe/database/database.py", line 112, in connect
    self._conn: "MariadbConnection" | "PostgresConnection" = self.get_connection()
                                                             ^^^^^^^^^^^^^^^^^^^^^
  File "/mnt/c/Users/HP/neilla/frappe-bench/frappe-bench/apps/frappe/frappe/database/mariadb/database.py", line 107, in get_connection
    conn = self._get_connection()
           ^^^^^^^^^^^^^^^^^^^^^^
  File "/mnt/c/Users/HP/neilla/frappe-bench/frappe-bench/apps/frappe/frappe/database/mariadb/database.py", line 113, in _get_connection
    return self.create_connection()
           ^^^^^^^^^^^^^^^^^^^^^^^^
  File "/mnt/c/Users/HP/neilla/frappe-bench/frappe-bench/apps/frappe/frappe/database/mariadb/database.py", line 116, in create_connection
    return pymysql.connect(**self.get_connection_settings())
           ^^^^^^^^^^^^^^^^^^^^^^^^^^^^^^^^^^^^^^^^^^^^^^^^^
  File "/mnt/c/Users/HP/neilla/frappe-bench/frappe-bench/env/lib/python3.12/site-packages/pymysql/connections.py", line 361, in __init__
    self.connect()
  File "/mnt/c/Users/HP/neilla/frappe-bench/frappe-bench/env/lib/python3.12/site-packages/pymysql/connections.py", line 669, in connect
    self._request_authentication()
  File "/mnt/c/Users/HP/neilla/frappe-bench/frappe-bench/env/lib/python3.12/site-packages/pymysql/connections.py", line 957, in _request_authentication
    auth_packet = self._read_packet()
                  ^^^^^^^^^^^^^^^^^^^
  File "/mnt/c/Users/HP/neilla/frappe-bench/frappe-bench/env/lib/python3.12/site-packages/pymysql/connections.py", line 775, in _read_packet
    packet.raise_for_error()
  File "/mnt/c/Users/HP/neilla/frappe-bench/frappe-bench/env/lib/python3.12/site-packages/pymysql/protocol.py", line 219, in raise_for_error
    err.raise_mysql_exception(self._data)
  File "/mnt/c/Users/HP/neilla/frappe-bench/frappe-bench/env/lib/python3.12/site-packages/pymysql/err.py", line 150, in raise_mysql_exception
    raise errorclass(errno, errval)
pymysql.err.OperationalError: (1049, "Unknown database '_cd931d51eba0e8ef'")
2025-04-18 02:31:07,801 ERROR scheduler Exception in Enqueue Events for Site emp.co.zw
Traceback (most recent call last):
  File "/mnt/c/Users/HP/neilla/frappe-bench/frappe-bench/apps/frappe/frappe/utils/scheduler.py", line 99, in enqueue_events_for_site
    if is_scheduler_inactive():
       ^^^^^^^^^^^^^^^^^^^^^^^
  File "/mnt/c/Users/HP/neilla/frappe-bench/frappe-bench/apps/frappe/frappe/utils/scheduler.py", line 143, in is_scheduler_inactive
    if is_scheduler_disabled(verbose=verbose):
       ^^^^^^^^^^^^^^^^^^^^^^^^^^^^^^^^^^^^^^
  File "/mnt/c/Users/HP/neilla/frappe-bench/frappe-bench/apps/frappe/frappe/utils/scheduler.py", line 156, in is_scheduler_disabled
    frappe.db.get_single_value("System Settings", "enable_scheduler")
  File "/mnt/c/Users/HP/neilla/frappe-bench/frappe-bench/apps/frappe/frappe/database/database.py", line 837, in get_single_value
    ).run()
      ^^^^^
  File "/mnt/c/Users/HP/neilla/frappe-bench/frappe-bench/apps/frappe/frappe/query_builder/utils.py", line 87, in execute_query
    result = frappe.db.sql(query, params, *args, **kwargs)  # nosemgrep
             ^^^^^^^^^^^^^^^^^^^^^^^^^^^^^^^^^^^^^^^^^^^^^
  File "/mnt/c/Users/HP/neilla/frappe-bench/frappe-bench/apps/frappe/frappe/database/database.py", line 207, in sql
    self.connect()
  File "/mnt/c/Users/HP/neilla/frappe-bench/frappe-bench/apps/frappe/frappe/database/database.py", line 112, in connect
    self._conn: "MariadbConnection" | "PostgresConnection" = self.get_connection()
                                                             ^^^^^^^^^^^^^^^^^^^^^
  File "/mnt/c/Users/HP/neilla/frappe-bench/frappe-bench/apps/frappe/frappe/database/mariadb/database.py", line 107, in get_connection
    conn = self._get_connection()
           ^^^^^^^^^^^^^^^^^^^^^^
  File "/mnt/c/Users/HP/neilla/frappe-bench/frappe-bench/apps/frappe/frappe/database/mariadb/database.py", line 113, in _get_connection
    return self.create_connection()
           ^^^^^^^^^^^^^^^^^^^^^^^^
  File "/mnt/c/Users/HP/neilla/frappe-bench/frappe-bench/apps/frappe/frappe/database/mariadb/database.py", line 116, in create_connection
    return pymysql.connect(**self.get_connection_settings())
           ^^^^^^^^^^^^^^^^^^^^^^^^^^^^^^^^^^^^^^^^^^^^^^^^^
  File "/mnt/c/Users/HP/neilla/frappe-bench/frappe-bench/env/lib/python3.12/site-packages/pymysql/connections.py", line 361, in __init__
    self.connect()
  File "/mnt/c/Users/HP/neilla/frappe-bench/frappe-bench/env/lib/python3.12/site-packages/pymysql/connections.py", line 669, in connect
    self._request_authentication()
  File "/mnt/c/Users/HP/neilla/frappe-bench/frappe-bench/env/lib/python3.12/site-packages/pymysql/connections.py", line 957, in _request_authentication
    auth_packet = self._read_packet()
                  ^^^^^^^^^^^^^^^^^^^
  File "/mnt/c/Users/HP/neilla/frappe-bench/frappe-bench/env/lib/python3.12/site-packages/pymysql/connections.py", line 775, in _read_packet
    packet.raise_for_error()
  File "/mnt/c/Users/HP/neilla/frappe-bench/frappe-bench/env/lib/python3.12/site-packages/pymysql/protocol.py", line 219, in raise_for_error
    err.raise_mysql_exception(self._data)
  File "/mnt/c/Users/HP/neilla/frappe-bench/frappe-bench/env/lib/python3.12/site-packages/pymysql/err.py", line 150, in raise_mysql_exception
    raise errorclass(errno, errval)
pymysql.err.OperationalError: (1049, "Unknown database '_cd931d51eba0e8ef'")
